Workbook

Sheet Instructions
A1: Resource Loading Schedule — September to Year End
A4: Purpose | B4: Week-by-week field resource requirement, Sept 2026 to year end, so we can see where crews are needed and when.
A6: PMs — what to do | B6: Open YOUR tab (named for you). Enter FTE per week against each row. FTE = full-time equivalents, e.g. 2.5 = two and a half people that week.
A8: Two ways to enter | B8: Both roll up identically — use whichever suits the job.
A9: Option A — by Job | B9: Your live jobs are already listed. Pick the Trade for the row, then enter FTE by week. Need more than one trade on a job? Copy the row and change the Trade.
A10: Option B — by Client | B10: Don't want job-level detail? Use the blank rows at the bottom: leave Job # empty, choose the Client and Trade, then enter FTE by week.
A12: Cells you edit | B12: Yellow cells only. Everything else is a formula — please don't overwrite.
A13: Blue text | B13: A number you typed in.
A14: Green text | B14: A figure pulled from another tab.
A16: Summaries | B16: 'Summary - Trade' and 'Summary - Client' are 100% formula driven and update themselves. Nothing to fill in there.
A18: Adding rows | B18: Insert anywhere between rows 4 and 400 on your tab — the summaries already cover that range.
A19: Trades list | B19: Held on the 'Lists' tab. If a trade is missing, add it there and it appears in the dropdowns and on the summary.
A21: ASSUMPTION — please confirm | B21: The trade list is a first pass and has NOT been agreed. Ken / PMs to confirm the categories before this goes out.
... A23: Source | B23: Job, client and PM data from the 'Input - Project List' tab (205 active jobs).
A26: EXAMPLE — how a filled row looks
A27: Job # | B27: Description | C27: Client | D27: Contract | E27: Trade | F27: 05-Sep | G27: 12-Sep | H27: 19-Sep
A28: 01-26-020 | B28: Nova Corunna - Heater BA-2107 | C28: Nova Chemicals Corporation | D28: T&M | E28: Boilermaker | F28: 4 | G28: 4 | H28: 2.5
B29: (leave blank = plan by client) | C29: Shell Canada Products | E29: Pipefitter / Steamfitter | F29: 2 | G29: 2
A30: Row 1 is job-level. Row 2 is client-level — Job # left blank. Both add into the same summary totals.

Sheet Summary - Trade
A1: RESOURCE SUMMARY — FTE by Trade and Week Ending
A2: Formula driven. Pulls from every PM tab — nothing to fill in here.
A3: Trade | B3: 46270 | C3: 46277 | D3: 46284 | E3: 46291 | F3: 46298 | G3: 46305 | H3: 46312 | I3: 46319 | J3: 46326 | K3: 46333 | L3: 46340 | M3: 46347 | N3: 46354 | O3: 46361 | P3: 46368 | Q3: 46375 | R3: 46382 | S3: 46389 | T3: Total
A4: Boilermaker | B4: =SUMIFS('Barrett, Ken'!F$4:F$31,'Barrett, Ken'!$E$4:$E$31,$A4)+SUMIFS('Brundage, Eric'!F$4:F$39,'Brundage, Eric'!$E$4:$E$39,$A4)+SUMIFS('Dubois, Joe'!F$4:F$70,'Dubois, Joe'!$E$4:$E$70,$A4)+SUMIFS('Gould, Kyle'!F$4:F$53,'Gould, Kyle'!$E$4:$E$53,$A4)+SUMIFS('Jamer, Douglas'!F$4:F$33,'Jamer, Douglas'!$E$4:$E$33,$A4)+SUMIFS('Kennedy, Michael'!F$4:F$87,'Kennedy, Michael'!$E$4:$E$87,$A4)+SUMIFS('Kennedy, Vince'!F$4:F$29,'Kennedy, Vince'!$E$4:$E$29,$A4)+SUMIFS('Morningstar, Jeremy J'!F$4:F$50,'Morningstar, Jeremy J'!$E$4:$E$50,$A4)+SUMIFS('Pendlebury, Jay'!F$4:F$31,'Pendlebury, Jay'!$E$4:$E$31,$A4)+SUMIFS('Poore, Jordan'!F$4:F$32,'Poore, Jordan'!$E$4:$E$32,$A4)+SUMIFS('Powers, Dave'!F$4:F$58,'Powers, Dave'!$E$4:$E$58,$A4) -> 0 | C4: =SUMIFS('Barrett, Ken'!G$4:G$31,'Barrett, Ken'!$E$4:$E$31,$A4)+SUMIFS('Brundage, Eric'!G$4:G$39,'Brundage, Eric'!$E$4:$E$39,$A4)+SUMIFS('Dubois, Joe'!G$4:G$70,'Dubois, Joe'!$E$4:$E$70,$A4)+SUMIFS('Gould, Kyle'!G$4:G$53,'Gould, Kyle'!$E$4:$E$53,$A4)+SUMIFS('Jamer, Douglas'!G$4:G$33,'Jamer, Douglas'!$E$4:$E$33,$A4)+SUMIFS('Kennedy, Michael'!G$4:G$87,'Kennedy, Michael'!$E$4:$E$87,$A4)+SUMIFS('Kennedy, Vince'!G$4:G$29,'Kennedy, Vince'!$E$4:$E$29,$A4)+SUMIFS('Morningstar, Jeremy J'!G$4:G$50,'Morningstar, Jeremy J'!$E$4:$E$50,$A4)+SUMIFS('Pendlebury, Jay'!G$4:G$31,'Pendlebury, Jay'!$E$4:$E$31,$A4)+SUMIFS('Poore, Jordan'!G$4:G$32,'Poore, Jordan'!$E$4:$E$32,$A4)+SUMIFS('Powers, Dave'!G$4:G$58,'Powers, Dave'!$E$4:$E$58,$A4) -> 0 | D4: =SUMIFS('Barrett, Ken'!H$4:H$31,'Barrett, Ken'!$E$4:$E$31,$A4)+SUMIFS('Brundage, Eric'!H$4:H$39,'Brundage, Eric'!$E$4:$E$39,$A4)+SUMIFS('Dubois, Joe'!H$4:H$70,'Dubois, Joe'!$E$4:$E$70,$A4)+SUMIFS('Gould, Kyle'!H$4:H$53,'Gould, Kyle'!$E$4:$E$53,$A4)+SUMIFS('Jamer, Douglas'!H$4:H$33,'Jamer, Douglas'!$E$4:$E$33,$A4)+SUMIFS('Kennedy, Michael'!H$4:H$87,'Kennedy, Michael'!$E$4:$E$87,$A4)+SUMIFS('Kennedy, Vince'!H$4:H$29,'Kennedy, Vince'!$E$4:$E$29,$A4)+SUMIFS('Morningstar, Jeremy J'!H$4:H$50,'Morningstar, Jeremy J'!$E$4:$E$50,$A4)+SUMIFS('Pendlebury, Jay'!H$4:H$31,'Pendlebury, Jay'!$E$4:$E$31,$A4)+SUMIFS('Poore, Jordan'!H$4:H$32,'Poore, Jordan'!$E$4:$E$32,$A4)+SUMIFS('Powers, Dave'!H$4:H$58,'Powers, Dave'!$E$4:$E$58,$A4) -> 0 | E4: =SUMIFS('Barrett, Ken'!I$4:I$31,'Barrett, Ken'!$E$4:$E$31,$A4)+SUMIFS('Brundage, Eric'!I$4:I$39,'Brundage, Eric'!$E$4:$E$39,$A4)+SUMIFS('Dubois, Joe'!I$4:I$70,'Dubois, Joe'!$E$4:$E$70,$A4)+SUMIFS('Gould, Kyle'!I$4:I$53,'Gould, Kyle'!$E$4:$E$53,$A4)+SUMIFS('Jamer, Douglas'!I$4:I$33,'Jamer, Douglas'!$E$4:$E$33,$A4)+SUMIFS('Kennedy, Michael'!I$4:I$87,'Kennedy, Michael'!$E$4:$E$87,$A4)+SUMIFS('Kennedy, Vince'!I$4:I$29,'Kennedy, Vince'!$E$4:$E$29,$A4)+SUMIFS('Morningstar, Jeremy J'!I$4:I$50,'Morningstar, Jeremy J'!$E$4:$E$50,$A4)+SUMIFS('Pendlebury, Jay'!I$4:I$31,'Pendlebury, Jay'!$E$4:$E$31,$A4)+SUMIFS('Poore, Jordan'!I$4:I$32,'Poore, Jordan'!$E$4:$E$32,$A4)+SUMIFS('Powers, Dave'!I$4:I$58,'Powers, Dave'!$E$4:$E$58,$A4) -> 0 | F4: =SUMIFS('Barrett, Ken'!J$4:J$31,'Barrett, Ken'!$E$4:$E$31,$A4)+SUMIFS('Brundage, Eric'!J$4:J$39,'Brundage, Eric'!$E$4:$E$39,$A4)+SUMIFS('Dubois, Joe'!J$4:J$70,'Dubois, Joe'!$E$4:$E$70,$A4)+SUMIFS('Gould, Kyle'!J$4:J$53,'Gould, Kyle'!$E$4:$E$53,$A4)+SUMIFS('Jamer, Douglas'!J$4:J$33,'Jamer, Douglas'!$E$4:$E$33,$A4)+SUMIFS('Kennedy, Michael'!J$4:J$87,'Kennedy, Michael'!$E$4:$E$87,$A4)+SUMIFS('Kennedy, Vince'!J$4:J$29,'Kennedy, Vince'!$E$4:$E$29,$A4)+SUMIFS('Morningstar, Jeremy J'!J$4:J$50,'Morningstar, Jeremy J'!$E$4:$E$50,$A4)+SUMIFS('Pendlebury, Jay'!J$4:J$31,'Pendlebury, Jay'!$E$4:$E$31,$A4)+SUMIFS('Poore, Jordan'!J$4:J$32,'Poore, Jordan'!$E$4:$E$32,$A4)+SUMIFS('Powers, Dave'!J$4:J$58,'Powers, Dave'!$E$4:$E$58,$A4) -> 0 | G4: =SUMIFS('Barrett, Ken'!K$4:K$31,'Barrett, Ken'!$E$4:$E$31,$A4)+SUMIFS('Brundage, Eric'!K$4:K$39,'Brundage, Eric'!$E$4:$E$39,$A4)+SUMIFS('Dubois, Joe'!K$4:K$70,'Dubois, Joe'!$E$4:$E$70,$A4)+SUMIFS('Gould, Kyle'!K$4:K$53,'Gould, Kyle'!$E$4:$E$53,$A4)+SUMIFS('Jamer, Douglas'!K$4:K$33,'Jamer, Douglas'!$E$4:$E$33,$A4)+SUMIFS('Kennedy, Michael'!K$4:K$87,'Kennedy, Michael'!$E$4:$E$87,$A4)+SUMIFS('Kennedy, Vince'!K$4:K$29,'Kennedy, Vince'!$E$4:$E$29,$A4)+SUMIFS('Morningstar, Jeremy J'!K$4:K$50,'Morningstar, Jeremy J'!$E$4:$E$50,$A4)+SUMIFS('Pendlebury, Jay'!K$4:K$31,'Pendlebury, Jay'!$E$4:$E$31,$A4)+SUMIFS('Poore, Jordan'!K$4:K$32,'Poore, Jordan'!$E$4:$E$32,$A4)+SUMIFS('Powers, Dave'!K$4:K$58,'Powers, Dave'!$E$4:$E$58,$A4) -> 0 | H4: =SUMIFS('Barrett, Ken'!L$4:L$31,'Barrett, Ken'!$E$4:$E$31,$A4)+SUMIFS('Brundage, Eric'!L$4:L$39,'Brundage, Eric'!$E$4:$E$39,$A4)+SUMIFS('Dubois, Joe'!L$4:L$70,'Dubois, Joe'!$E$4:$E$70,$A4)+SUMIFS('Gould, Kyle'!L$4:L$53,'Gould, Kyle'!$E$4:$E$53,$A4)+SUMIFS('Jamer, Douglas'!L$4:L$33,'Jamer, Douglas'!$E$4:$E$33,$A4)+SUMIFS('Kennedy, Michael'!L$4:L$87,'Kennedy, Michael'!$E$4:$E$87,$A4)+SUMIFS('Kennedy, Vince'!L$4:L$29,'Kennedy, Vince'!$E$4:$E$29,$A4)+SUMIFS('Morningstar, Jeremy J'!L$4:L$50,'Morningstar, Jeremy J'!$E$4:$E$50,$A4)+SUMIFS('Pendlebury, Jay'!L$4:L$31,'Pendlebury, Jay'!$E$4:$E$31,$A4)+SUMIFS('Poore, Jordan'!L$4:L$32,'Poore, Jordan'!$E$4:$E$32,$A4)+SUMIFS('Powers, Dave'!L$4:L$58,'Powers, Dave'!$E$4:$E$58,$A4) -> 0 | I4: =SUMIFS('Barrett, Ken'!M$4:M$31,'Barrett, Ken'!$E$4:$E$31,$A4)+SUMIFS('Brundage, Eric'!M$4:M$39,'Brundage, Eric'!$E$4:$E$39,$A4)+SUMIFS('Dubois, Joe'!M$4:M$70,'Dubois, Joe'!$E$4:$E$70,$A4)+SUMIFS('Gould, Kyle'!M$4:M$53,'Gould, Kyle'!$E$4:$E$53,$A4)+SUMIFS('Jamer, Douglas'!M$4:M$33,'Jamer, Douglas'!$E$4:$E$33,$A4)+SUMIFS('Kennedy, Michael'!M$4:M$87,'Kennedy, Michael'!$E$4:$E$87,$A4)+SUMIFS('Kennedy, Vince'!M$4:M$29,'Kennedy, Vince'!$E$4:$E$29,$A4)+SUMIFS('Morningstar, Jeremy J'!M$4:M$50,'Morningstar, Jeremy J'!$E$4:$E$50,$A4)+SUMIFS('Pendlebury, Jay'!M$4:M$31,'Pendlebury, Jay'!$E$4:$E$31,$A4)+SUMIFS('Poore, Jordan'!M$4:M$32,'Poore, Jordan'!$E$4:$E$32,$A4)+SUMIFS('Powers, Dave'!M$4:M$58,'Powers, Dave'!$E$4:$E$58,$A4) -> 0 | ... S4: =SUMIFS('Barrett, Ken'!W$4:W$31,'Barrett, Ken'!$E$4:$E$31,$A4)+SUMIFS('Brundage, Eric'!W$4:W$39,'Brundage, Eric'!$E$4:$E$39,$A4)+SUMIFS('Dubois, Joe'!W$4:W$70,'Dubois, Joe'!$E$4:$E$70,$A4)+SUMIFS('Gould, Kyle'!W$4:W$53,'Gould, Kyle'!$E$4:$E$53,$A4)+SUMIFS('Jamer, Douglas'!W$4:W$33,'Jamer, Douglas'!$E$4:$E$33,$A4)+SUMIFS('Kennedy, Michael'!W$4:W$87,'Kennedy, Michael'!$E$4:$E$87,$A4)+SUMIFS('Kennedy, Vince'!W$4:W$29,'Kennedy, Vince'!$E$4:$E$29,$A4)+SUMIFS('Morningstar, Jeremy J'!W$4:W$50,'Morningstar, Jeremy J'!$E$4:$E$50,$A4)+SUMIFS('Pendlebury, Jay'!W$4:W$31,'Pendlebury, Jay'!$E$4:$E$31,$A4)+SUMIFS('Poore, Jordan'!W$4:W$32,'Poore, Jordan'!$E$4:$E$32,$A4)+SUMIFS('Powers, Dave'!W$4:W$58,'Powers, Dave'!$E$4:$E$58,$A4) -> 0 | T4: =SUM(B4:S4) -> 0
A5: Pipefitter / Steamfitter | B5: =SUMIFS('Barrett, Ken'!F$4:F$31,'Barrett, Ken'!$E$4:$E$31,$A5)+SUMIFS('Brundage, Eric'!F$4:F$39,'Brundage, Eric'!$E$4:$E$39,$A5)+SUMIFS('Dubois, Joe'!F$4:F$70,'Dubois, Joe'!$E$4:$E$70,$A5)+SUMIFS('Gould, Kyle'!F$4:F$53,'Gould, Kyle'!$E$4:$E$53,$A5)+SUMIFS('Jamer, Douglas'!F$4:F$33,'Jamer, Douglas'!$E$4:$E$33,$A5)+SUMIFS('Kennedy, Michael'!F$4:F$87,'Kennedy, Michael'!$E$4:$E$87,$A5)+SUMIFS('Kennedy, Vince'!F$4:F$29,'Kennedy, Vince'!$E$4:$E$29,$A5)+SUMIFS('Morningstar, Jeremy J'!F$4:F$50,'Morningstar, Jeremy J'!$E$4:$E$50,$A5)+SUMIFS('Pendlebury, Jay'!F$4:F$31,'Pendlebury, Jay'!$E$4:$E$31,$A5)+SUMIFS('Poore, Jordan'!F$4:F$32,'Poore, Jordan'!$E$4:$E$32,$A5)+SUMIFS('Powers, Dave'!F$4:F$58,'Powers, Dave'!$E$4:$E$58,$A5) -> 0 | C5: =SUMIFS('Barrett, Ken'!G$4:G$31,'Barrett, Ken'!$E$4:$E$31,$A5)+SUMIFS('Brundage, Eric'!G$4:G$39,'Brundage, Eric'!$E$4:$E$39,$A5)+SUMIFS('Dubois, Joe'!G$4:G$70,'Dubois, Joe'!$E$4:$E$70,$A5)+SUMIFS('Gould, Kyle'!G$4:G$53,'Gould, Kyle'!$E$4:$E$53,$A5)+SUMIFS('Jamer, Douglas'!G$4:G$33,'Jamer, Douglas'!$E$4:$E$33,$A5)+SUMIFS('Kennedy, Michael'!G$4:G$87,'Kennedy, Michael'!$E$4:$E$87,$A5)+SUMIFS('Kennedy, Vince'!G$4:G$29,'Kennedy, Vince'!$E$4:$E$29,$A5)+SUMIFS('Morningstar, Jeremy J'!G$4:G$50,'Morningstar, Jeremy J'!$E$4:$E$50,$A5)+SUMIFS('Pendlebury, Jay'!G$4:G$31,'Pendlebury, Jay'!$E$4:$E$31,$A5)+SUMIFS('Poore, Jordan'!G$4:G$32,'Poore, Jordan'!$E$4:$E$32,$A5)+SUMIFS('Powers, Dave'!G$4:G$58,'Powers, Dave'!$E$4:$E$58,$A5) -> 0 | D5: =SUMIFS('Barrett, Ken'!H$4:H$31,'Barrett, Ken'!$E$4:$E$31,$A5)+SUMIFS('Brundage, Eric'!H$4:H$39,'Brundage, Eric'!$E$4:$E$39,$A5)+SUMIFS('Dubois, Joe'!H$4:H$70,'Dubois, Joe'!$E$4:$E$70,$A5)+SUMIFS('Gould, Kyle'!H$4:H$53,'Gould, Kyle'!$E$4:$E$53,$A5)+SUMIFS('Jamer, Douglas'!H$4:H$33,'Jamer, Douglas'!$E$4:$E$33,$A5)+SUMIFS('Kennedy, Michael'!H$4:H$87,'Kennedy, Michael'!$E$4:$E$87,$A5)+SUMIFS('Kennedy, Vince'!H$4:H$29,'Kennedy, Vince'!$E$4:$E$29,$A5)+SUMIFS('Morningstar, Jeremy J'!H$4:H$50,'Morningstar, Jeremy J'!$E$4:$E$50,$A5)+SUMIFS('Pendlebury, Jay'!H$4:H$31,'Pendlebury, Jay'!$E$4:$E$31,$A5)+SUMIFS('Poore, Jordan'!H$4:H$32,'Poore, Jordan'!$E$4:$E$32,$A5)+SUMIFS('Powers, Dave'!H$4:H$58,'Powers, Dave'!$E$4:$E$58,$A5) -> 0 | E5: =SUMIFS('Barrett, Ken'!I$4:I$31,'Barrett, Ken'!$E$4:$E$31,$A5)+SUMIFS('Brundage, Eric'!I$4:I$39,'Brundage, Eric'!$E$4:$E$39,$A5)+SUMIFS('Dubois, Joe'!I$4:I$70,'Dubois, Joe'!$E$4:$E$70,$A5)+SUMIFS('Gould, Kyle'!I$4:I$53,'Gould, Kyle'!$E$4:$E$53,$A5)+SUMIFS('Jamer, Douglas'!I$4:I$33,'Jamer, Douglas'!$E$4:$E$33,$A5)+SUMIFS('Kennedy, Michael'!I$4:I$87,'Kennedy, Michael'!$E$4:$E$87,$A5)+SUMIFS('Kennedy, Vince'!I$4:I$29,'Kennedy, Vince'!$E$4:$E$29,$A5)+SUMIFS('Morningstar, Jeremy J'!I$4:I$50,'Morningstar, Jeremy J'!$E$4:$E$50,$A5)+SUMIFS('Pendlebury, Jay'!I$4:I$31,'Pendlebury, Jay'!$E$4:$E$31,$A5)+SUMIFS('Poore, Jordan'!I$4:I$32,'Poore, Jordan'!$E$4:$E$32,$A5)+SUMIFS('Powers, Dave'!I$4:I$58,'Powers, Dave'!$E$4:$E$58,$A5) -> 0 | F5: =SUMIFS('Barrett, Ken'!J$4:J$31,'Barrett, Ken'!$E$4:$E$31,$A5)+SUMIFS('Brundage, Eric'!J$4:J$39,'Brundage, Eric'!$E$4:$E$39,$A5)+SUMIFS('Dubois, Joe'!J$4:J$70,'Dubois, Joe'!$E$4:$E$70,$A5)+SUMIFS('Gould, Kyle'!J$4:J$53,'Gould, Kyle'!$E$4:$E$53,$A5)+SUMIFS('Jamer, Douglas'!J$4:J$33,'Jamer, Douglas'!$E$4:$E$33,$A5)+SUMIFS('Kennedy, Michael'!J$4:J$87,'Kennedy, Michael'!$E$4:$E$87,$A5)+SUMIFS('Kennedy, Vince'!J$4:J$29,'Kennedy, Vince'!$E$4:$E$29,$A5)+SUMIFS('Morningstar, Jeremy J'!J$4:J$50,'Morningstar, Jeremy J'!$E$4:$E$50,$A5)+SUMIFS('Pendlebury, Jay'!J$4:J$31,'Pendlebury, Jay'!$E$4:$E$31,$A5)+SUMIFS('Poore, Jordan'!J$4:J$32,'Poore, Jordan'!$E$4:$E$32,$A5)+SUMIFS('Powers, Dave'!J$4:J$58,'Powers, Dave'!$E$4:$E$58,$A5) -> 0 | G5: =SUMIFS('Barrett, Ken'!K$4:K$31,'Barrett, Ken'!$E$4:$E$31,$A5)+SUMIFS('Brundage, Eric'!K$4:K$39,'Brundage, Eric'!$E$4:$E$39,$A5)+SUMIFS('Dubois, Joe'!K$4:K$70,'Dubois, Joe'!$E$4:$E$70,$A5)+SUMIFS('Gould, Kyle'!K$4:K$53,'Gould, Kyle'!$E$4:$E$53,$A5)+SUMIFS('Jamer, Douglas'!K$4:K$33,'Jamer, Douglas'!$E$4:$E$33,$A5)+SUMIFS('Kennedy, Michael'!K$4:K$87,'Kennedy, Michael'!$E$4:$E$87,$A5)+SUMIFS('Kennedy, Vince'!K$4:K$29,'Kennedy, Vince'!$E$4:$E$29,$A5)+SUMIFS('Morningstar, Jeremy J'!K$4:K$50,'Morningstar, Jeremy J'!$E$4:$E$50,$A5)+SUMIFS('Pendlebury, Jay'!K$4:K$31,'Pendlebury, Jay'!$E$4:$E$31,$A5)+SUMIFS('Poore, Jordan'!K$4:K$32,'Poore, Jordan'!$E$4:$E$32,$A5)+SUMIFS('Powers, Dave'!K$4:K$58,'Powers, Dave'!$E$4:$E$58,$A5) -> 0 | H5: =SUMIFS('Barrett, Ken'!L$4:L$31,'Barrett, Ken'!$E$4:$E$31,$A5)+SUMIFS('Brundage, Eric'!L$4:L$39,'Brundage, Eric'!$E$4:$E$39,$A5)+SUMIFS('Dubois, Joe'!L$4:L$70,'Dubois, Joe'!$E$4:$E$70,$A5)+SUMIFS('Gould, Kyle'!L$4:L$53,'Gould, Kyle'!$E$4:$E$53,$A5)+SUMIFS('Jamer, Douglas'!L$4:L$33,'Jamer, Douglas'!$E$4:$E$33,$A5)+SUMIFS('Kennedy, Michael'!L$4:L$87,'Kennedy, Michael'!$E$4:$E$87,$A5)+SUMIFS('Kennedy, Vince'!L$4:L$29,'Kennedy, Vince'!$E$4:$E$29,$A5)+SUMIFS('Morningstar, Jeremy J'!L$4:L$50,'Morningstar, Jeremy J'!$E$4:$E$50,$A5)+SUMIFS('Pendlebury, Jay'!L$4:L$31,'Pendlebury, Jay'!$E$4:$E$31,$A5)+SUMIFS('Poore, Jordan'!L$4:L$32,'Poore, Jordan'!$E$4:$E$32,$A5)+SUMIFS('Powers, Dave'!L$4:L$58,'Powers, Dave'!$E$4:$E$58,$A5) -> 0 | I5: =SUMIFS('Barrett, Ken'!M$4:M$31,'Barrett, Ken'!$E$4:$E$31,$A5)+SUMIFS('Brundage, Eric'!M$4:M$39,'Brundage, Eric'!$E$4:$E$39,$A5)+SUMIFS('Dubois, Joe'!M$4:M$70,'Dubois, Joe'!$E$4:$E$70,$A5)+SUMIFS('Gould, Kyle'!M$4:M$53,'Gould, Kyle'!$E$4:$E$53,$A5)+SUMIFS('Jamer, Douglas'!M$4:M$33,'Jamer, Douglas'!$E$4:$E$33,$A5)+SUMIFS('Kennedy, Michael'!M$4:M$87,'Kennedy, Michael'!$E$4:$E$87,$A5)+SUMIFS('Kennedy, Vince'!M$4:M$29,'Kennedy, Vince'!$E$4:$E$29,$A5)+SUMIFS('Morningstar, Jeremy J'!M$4:M$50,'Morningstar, Jeremy J'!$E$4:$E$50,$A5)+SUMIFS('Pendlebury, Jay'!M$4:M$31,'Pendlebury, Jay'!$E$4:$E$31,$A5)+SUMIFS('Poore, Jordan'!M$4:M$32,'Poore, Jordan'!$E$4:$E$32,$A5)+SUMIFS('Powers, Dave'!M$4:M$58,'Powers, Dave'!$E$4:$E$58,$A5) -> 0 | ... S5: =SUMIFS('Barrett, Ken'!W$4:W$31,'Barrett, Ken'!$E$4:$E$31,$A5)+SUMIFS('Brundage, Eric'!W$4:W$39,'Brundage, Eric'!$E$4:$E$39,$A5)+SUMIFS('Dubois, Joe'!W$4:W$70,'Dubois, Joe'!$E$4:$E$70,$A5)+SUMIFS('Gould, Kyle'!W$4:W$53,'Gould, Kyle'!$E$4:$E$53,$A5)+SUMIFS('Jamer, Douglas'!W$4:W$33,'Jamer, Douglas'!$E$4:$E$33,$A5)+SUMIFS('Kennedy, Michael'!W$4:W$87,'Kennedy, Michael'!$E$4:$E$87,$A5)+SUMIFS('Kennedy, Vince'!W$4:W$29,'Kennedy, Vince'!$E$4:$E$29,$A5)+SUMIFS('Morningstar, Jeremy J'!W$4:W$50,'Morningstar, Jeremy J'!$E$4:$E$50,$A5)+SUMIFS('Pendlebury, Jay'!W$4:W$31,'Pendlebury, Jay'!$E$4:$E$31,$A5)+SUMIFS('Poore, Jordan'!W$4:W$32,'Poore, Jordan'!$E$4:$E$32,$A5)+SUMIFS('Powers, Dave'!W$4:W$58,'Powers, Dave'!$E$4:$E$58,$A5) -> 0 | T5: =SUM(B5:S5) -> 0
A6: Welder | B6: =SUMIFS('Barrett, Ken'!F$4:F$31,'Barrett, Ken'!$E$4:$E$31,$A6)+SUMIFS('Brundage, Eric'!F$4:F$39,'Brundage, Eric'!$E$4:$E$39,$A6)+SUMIFS('Dubois, Joe'!F$4:F$70,'Dubois, Joe'!$E$4:$E$70,$A6)+SUMIFS('Gould, Kyle'!F$4:F$53,'Gould, Kyle'!$E$4:$E$53,$A6)+SUMIFS('Jamer, Douglas'!F$4:F$33,'Jamer, Douglas'!$E$4:$E$33,$A6)+SUMIFS('Kennedy, Michael'!F$4:F$87,'Kennedy, Michael'!$E$4:$E$87,$A6)+SUMIFS('Kennedy, Vince'!F$4:F$29,'Kennedy, Vince'!$E$4:$E$29,$A6)+SUMIFS('Morningstar, Jeremy J'!F$4:F$50,'Morningstar, Jeremy J'!$E$4:$E$50,$A6)+SUMIFS('Pendlebury, Jay'!F$4:F$31,'Pendlebury, Jay'!$E$4:$E$31,$A6)+SUMIFS('Poore, Jordan'!F$4:F$32,'Poore, Jordan'!$E$4:$E$32,$A6)+SUMIFS('Powers, Dave'!F$4:F$58,'Powers, Dave'!$E$4:$E$58,$A6) -> 0 | C6: =SUMIFS('Barrett, Ken'!G$4:G$31,'Barrett, Ken'!$E$4:$E$31,$A6)+SUMIFS('Brundage, Eric'!G$4:G$39,'Brundage, Eric'!$E$4:$E$39,$A6)+SUMIFS('Dubois, Joe'!G$4:G$70,'Dubois, Joe'!$E$4:$E$70,$A6)+SUMIFS('Gould, Kyle'!G$4:G$53,'Gould, Kyle'!$E$4:$E$53,$A6)+SUMIFS('Jamer, Douglas'!G$4:G$33,'Jamer, Douglas'!$E$4:$E$33,$A6)+SUMIFS('Kennedy, Michael'!G$4:G$87,'Kennedy, Michael'!$E$4:$E$87,$A6)+SUMIFS('Kennedy, Vince'!G$4:G$29,'Kennedy, Vince'!$E$4:$E$29,$A6)+SUMIFS('Morningstar, Jeremy J'!G$4:G$50,'Morningstar, Jeremy J'!$E$4:$E$50,$A6)+SUMIFS('Pendlebury, Jay'!G$4:G$31,'Pendlebury, Jay'!$E$4:$E$31,$A6)+SUMIFS('Poore, Jordan'!G$4:G$32,'Poore, Jordan'!$E$4:$E$32,$A6)+SUMIFS('Powers, Dave'!G$4:G$58,'Powers, Dave'!$E$4:$E$58,$A6) -> 0 | D6: =SUMIFS('Barrett, Ken'!H$4:H$31,'Barrett, Ken'!$E$4:$E$31,$A6)+SUMIFS('Brundage, Eric'!H$4:H$39,'Brundage, Eric'!$E$4:$E$39,$A6)+SUMIFS('Dubois, Joe'!H$4:H$70,'Dubois, Joe'!$E$4:$E$70,$A6)+SUMIFS('Gould, Kyle'!H$4:H$53,'Gould, Kyle'!$E$4:$E$53,$A6)+SUMIFS('Jamer, Douglas'!H$4:H$33,'Jamer, Douglas'!$E$4:$E$33,$A6)+SUMIFS('Kennedy, Michael'!H$4:H$87,'Kennedy, Michael'!$E$4:$E$87,$A6)+SUMIFS('Kennedy, Vince'!H$4:H$29,'Kennedy, Vince'!$E$4:$E$29,$A6)+SUMIFS('Morningstar, Jeremy J'!H$4:H$50,'Morningstar, Jeremy J'!$E$4:$E$50,$A6)+SUMIFS('Pendlebury, Jay'!H$4:H$31,'Pendlebury, Jay'!$E$4:$E$31,$A6)+SUMIFS('Poore, Jordan'!H$4:H$32,'Poore, Jordan'!$E$4:$E$32,$A6)+SUMIFS('Powers, Dave'!H$4:H$58,'Powers, Dave'!$E$4:$E$58,$A6) -> 0 | E6: =SUMIFS('Barrett, Ken'!I$4:I$31,'Barrett, Ken'!$E$4:$E$31,$A6)+SUMIFS('Brundage, Eric'!I$4:I$39,'Brundage, Eric'!$E$4:$E$39,$A6)+SUMIFS('Dubois, Joe'!I$4:I$70,'Dubois, Joe'!$E$4:$E$70,$A6)+SUMIFS('Gould, Kyle'!I$4:I$53,'Gould, Kyle'!$E$4:$E$53,$A6)+SUMIFS('Jamer, Douglas'!I$4:I$33,'Jamer, Douglas'!$E$4:$E$33,$A6)+SUMIFS('Kennedy, Michael'!I$4:I$87,'Kennedy, Michael'!$E$4:$E$87,$A6)+SUMIFS('Kennedy, Vince'!I$4:I$29,'Kennedy, Vince'!$E$4:$E$29,$A6)+SUMIFS('Morningstar, Jeremy J'!I$4:I$50,'Morningstar, Jeremy J'!$E$4:$E$50,$A6)+SUMIFS('Pendlebury, Jay'!I$4:I$31,'Pendlebury, Jay'!$E$4:$E$31,$A6)+SUMIFS('Poore, Jordan'!I$4:I$32,'Poore, Jordan'!$E$4:$E$32,$A6)+SUMIFS('Powers, Dave'!I$4:I$58,'Powers, Dave'!$E$4:$E$58,$A6) -> 0 | F6: =SUMIFS('Barrett, Ken'!J$4:J$31,'Barrett, Ken'!$E$4:$E$31,$A6)+SUMIFS('Brundage, Eric'!J$4:J$39,'Brundage, Eric'!$E$4:$E$39,$A6)+SUMIFS('Dubois, Joe'!J$4:J$70,'Dubois, Joe'!$E$4:$E$70,$A6)+SUMIFS('Gould, Kyle'!J$4:J$53,'Gould, Kyle'!$E$4:$E$53,$A6)+SUMIFS('Jamer, Douglas'!J$4:J$33,'Jamer, Douglas'!$E$4:$E$33,$A6)+SUMIFS('Kennedy, Michael'!J$4:J$87,'Kennedy, Michael'!$E$4:$E$87,$A6)+SUMIFS('Kennedy, Vince'!J$4:J$29,'Kennedy, Vince'!$E$4:$E$29,$A6)+SUMIFS('Morningstar, Jeremy J'!J$4:J$50,'Morningstar, Jeremy J'!$E$4:$E$50,$A6)+SUMIFS('Pendlebury, Jay'!J$4:J$31,'Pendlebury, Jay'!$E$4:$E$31,$A6)+SUMIFS('Poore, Jordan'!J$4:J$32,'Poore, Jordan'!$E$4:$E$32,$A6)+SUMIFS('Powers, Dave'!J$4:J$58,'Powers, Dave'!$E$4:$E$58,$A6) -> 0 | G6: =SUMIFS('Barrett, Ken'!K$4:K$31,'Barrett, Ken'!$E$4:$E$31,$A6)+SUMIFS('Brundage, Eric'!K$4:K$39,'Brundage, Eric'!$E$4:$E$39,$A6)+SUMIFS('Dubois, Joe'!K$4:K$70,'Dubois, Joe'!$E$4:$E$70,$A6)+SUMIFS('Gould, Kyle'!K$4:K$53,'Gould, Kyle'!$E$4:$E$53,$A6)+SUMIFS('Jamer, Douglas'!K$4:K$33,'Jamer, Douglas'!$E$4:$E$33,$A6)+SUMIFS('Kennedy, Michael'!K$4:K$87,'Kennedy, Michael'!$E$4:$E$87,$A6)+SUMIFS('Kennedy, Vince'!K$4:K$29,'Kennedy, Vince'!$E$4:$E$29,$A6)+SUMIFS('Morningstar, Jeremy J'!K$4:K$50,'Morningstar, Jeremy J'!$E$4:$E$50,$A6)+SUMIFS('Pendlebury, Jay'!K$4:K$31,'Pendlebury, Jay'!$E$4:$E$31,$A6)+SUMIFS('Poore, Jordan'!K$4:K$32,'Poore, Jordan'!$E$4:$E$32,$A6)+SUMIFS('Powers, Dave'!K$4:K$58,'Powers, Dave'!$E$4:$E$58,$A6) -> 0 | H6: =SUMIFS('Barrett, Ken'!L$4:L$31,'Barrett, Ken'!$E$4:$E$31,$A6)+SUMIFS('Brundage, Eric'!L$4:L$39,'Brundage, Eric'!$E$4:$E$39,$A6)+SUMIFS('Dubois, Joe'!L$4:L$70,'Dubois, Joe'!$E$4:$E$70,$A6)+SUMIFS('Gould, Kyle'!L$4:L$53,'Gould, Kyle'!$E$4:$E$53,$A6)+SUMIFS('Jamer, Douglas'!L$4:L$33,'Jamer, Douglas'!$E$4:$E$33,$A6)+SUMIFS('Kennedy, Michael'!L$4:L$87,'Kennedy, Michael'!$E$4:$E$87,$A6)+SUMIFS('Kennedy, Vince'!L$4:L$29,'Kennedy, Vince'!$E$4:$E$29,$A6)+SUMIFS('Morningstar, Jeremy J'!L$4:L$50,'Morningstar, Jeremy J'!$E$4:$E$50,$A6)+SUMIFS('Pendlebury, Jay'!L$4:L$31,'Pendlebury, Jay'!$E$4:$E$31,$A6)+SUMIFS('Poore, Jordan'!L$4:L$32,'Poore, Jordan'!$E$4:$E$32,$A6)+SUMIFS('Powers, Dave'!L$4:L$58,'Powers, Dave'!$E$4:$E$58,$A6) -> 0 | I6: =SUMIFS('Barrett, Ken'!M$4:M$31,'Barrett, Ken'!$E$4:$E$31,$A6)+SUMIFS('Brundage, Eric'!M$4:M$39,'Brundage, Eric'!$E$4:$E$39,$A6)+SUMIFS('Dubois, Joe'!M$4:M$70,'Dubois, Joe'!$E$4:$E$70,$A6)+SUMIFS('Gould, Kyle'!M$4:M$53,'Gould, Kyle'!$E$4:$E$53,$A6)+SUMIFS('Jamer, Douglas'!M$4:M$33,'Jamer, Douglas'!$E$4:$E$33,$A6)+SUMIFS('Kennedy, Michael'!M$4:M$87,'Kennedy, Michael'!$E$4:$E$87,$A6)+SUMIFS('Kennedy, Vince'!M$4:M$29,'Kennedy, Vince'!$E$4:$E$29,$A6)+SUMIFS('Morningstar, Jeremy J'!M$4:M$50,'Morningstar, Jeremy J'!$E$4:$E$50,$A6)+SUMIFS('Pendlebury, Jay'!M$4:M$31,'Pendlebury, Jay'!$E$4:$E$31,$A6)+SUMIFS('Poore, Jordan'!M$4:M$32,'Poore, Jordan'!$E$4:$E$32,$A6)+SUMIFS('Powers, Dave'!M$4:M$58,'Powers, Dave'!$E$4:$E$58,$A6) -> 0 | ... S6: =SUMIFS('Barrett, Ken'!W$4:W$31,'Barrett, Ken'!$E$4:$E$31,$A6)+SUMIFS('Brundage, Eric'!W$4:W$39,'Brundage, Eric'!$E$4:$E$39,$A6)+SUMIFS('Dubois, Joe'!W$4:W$70,'Dubois, Joe'!$E$4:$E$70,$A6)+SUMIFS('Gould, Kyle'!W$4:W$53,'Gould, Kyle'!$E$4:$E$53,$A6)+SUMIFS('Jamer, Douglas'!W$4:W$33,'Jamer, Douglas'!$E$4:$E$33,$A6)+SUMIFS('Kennedy, Michael'!W$4:W$87,'Kennedy, Michael'!$E$4:$E$87,$A6)+SUMIFS('Kennedy, Vince'!W$4:W$29,'Kennedy, Vince'!$E$4:$E$29,$A6)+SUMIFS('Morningstar, Jeremy J'!W$4:W$50,'Morningstar, Jeremy J'!$E$4:$E$50,$A6)+SUMIFS('Pendlebury, Jay'!W$4:W$31,'Pendlebury, Jay'!$E$4:$E$31,$A6)+SUMIFS('Poore, Jordan'!W$4:W$32,'Poore, Jordan'!$E$4:$E$32,$A6)+SUMIFS('Powers, Dave'!W$4:W$58,'Powers, Dave'!$E$4:$E$58,$A6) -> 0 | T6: =SUM(B6:S6) -> 0
A7: Millwright | B7: =SUMIFS('Barrett, Ken'!F$4:F$31,'Barrett, Ken'!$E$4:$E$31,$A7)+SUMIFS('Brundage, Eric'!F$4:F$39,'Brundage, Eric'!$E$4:$E$39,$A7)+SUMIFS('Dubois, Joe'!F$4:F$70,'Dubois, Joe'!$E$4:$E$70,$A7)+SUMIFS('Gould, Kyle'!F$4:F$53,'Gould, Kyle'!$E$4:$E$53,$A7)+SUMIFS('Jamer, Douglas'!F$4:F$33,'Jamer, Douglas'!$E$4:$E$33,$A7)+SUMIFS('Kennedy, Michael'!F$4:F$87,'Kennedy, Michael'!$E$4:$E$87,$A7)+SUMIFS('Kennedy, Vince'!F$4:F$29,'Kennedy, Vince'!$E$4:$E$29,$A7)+SUMIFS('Morningstar, Jeremy J'!F$4:F$50,'Morningstar, Jeremy J'!$E$4:$E$50,$A7)+SUMIFS('Pendlebury, Jay'!F$4:F$31,'Pendlebury, Jay'!$E$4:$E$31,$A7)+SUMIFS('Poore, Jordan'!F$4:F$32,'Poore, Jordan'!$E$4:$E$32,$A7)+SUMIFS('Powers, Dave'!F$4:F$58,'Powers, Dave'!$E$4:$E$58,$A7) -> 0 | C7: =SUMIFS('Barrett, Ken'!G$4:G$31,'Barrett, Ken'!$E$4:$E$31,$A7)+SUMIFS('Brundage, Eric'!G$4:G$39,'Brundage, Eric'!$E$4:$E$39,$A7)+SUMIFS('Dubois, Joe'!G$4:G$70,'Dubois, Joe'!$E$4:$E$70,$A7)+SUMIFS('Gould, Kyle'!G$4:G$53,'Gould, Kyle'!$E$4:$E$53,$A7)+SUMIFS('Jamer, Douglas'!G$4:G$33,'Jamer, Douglas'!$E$4:$E$33,$A7)+SUMIFS('Kennedy, Michael'!G$4:G$87,'Kennedy, Michael'!$E$4:$E$87,$A7)+SUMIFS('Kennedy, Vince'!G$4:G$29,'Kennedy, Vince'!$E$4:$E$29,$A7)+SUMIFS('Morningstar, Jeremy J'!G$4:G$50,'Morningstar, Jeremy J'!$E$4:$E$50,$A7)+SUMIFS('Pendlebury, Jay'!G$4:G$31,'Pendlebury, Jay'!$E$4:$E$31,$A7)+SUMIFS('Poore, Jordan'!G$4:G$32,'Poore, Jordan'!$E$4:$E$32,$A7)+SUMIFS('Powers, Dave'!G$4:G$58,'Powers, Dave'!$E$4:$E$58,$A7) -> 0 | D7: =SUMIFS('Barrett, Ken'!H$4:H$31,'Barrett, Ken'!$E$4:$E$31,$A7)+SUMIFS('Brundage, Eric'!H$4:H$39,'Brundage, Eric'!$E$4:$E$39,$A7)+SUMIFS('Dubois, Joe'!H$4:H$70,'Dubois, Joe'!$E$4:$E$70,$A7)+SUMIFS('Gould, Kyle'!H$4:H$53,'Gould, Kyle'!$E$4:$E$53,$A7)+SUMIFS('Jamer, Douglas'!H$4:H$33,'Jamer, Douglas'!$E$4:$E$33,$A7)+SUMIFS('Kennedy, Michael'!H$4:H$87,'Kennedy, Michael'!$E$4:$E$87,$A7)+SUMIFS('Kennedy, Vince'!H$4:H$29,'Kennedy, Vince'!$E$4:$E$29,$A7)+SUMIFS('Morningstar, Jeremy J'!H$4:H$50,'Morningstar, Jeremy J'!$E$4:$E$50,$A7)+SUMIFS('Pendlebury, Jay'!H$4:H$31,'Pendlebury, Jay'!$E$4:$E$31,$A7)+SUMIFS('Poore, Jordan'!H$4:H$32,'Poore, Jordan'!$E$4:$E$32,$A7)+SUMIFS('Powers, Dave'!H$4:H$58,'Powers, Dave'!$E$4:$E$58,$A7) -> 0 | E7: =SUMIFS('Barrett, Ken'!I$4:I$31,'Barrett, Ken'!$E$4:$E$31,$A7)+SUMIFS('Brundage, Eric'!I$4:I$39,'Brundage, Eric'!$E$4:$E$39,$A7)+SUMIFS('Dubois, Joe'!I$4:I$70,'Dubois, Joe'!$E$4:$E$70,$A7)+SUMIFS('Gould, Kyle'!I$4:I$53,'Gould, Kyle'!$E$4:$E$53,$A7)+SUMIFS('Jamer, Douglas'!I$4:I$33,'Jamer, Douglas'!$E$4:$E$33,$A7)+SUMIFS('Kennedy, Michael'!I$4:I$87,'Kennedy, Michael'!$E$4:$E$87,$A7)+SUMIFS('Kennedy, Vince'!I$4:I$29,'Kennedy, Vince'!$E$4:$E$29,$A7)+SUMIFS('Morningstar, Jeremy J'!I$4:I$50,'Morningstar, Jeremy J'!$E$4:$E$50,$A7)+SUMIFS('Pendlebury, Jay'!I$4:I$31,'Pendlebury, Jay'!$E$4:$E$31,$A7)+SUMIFS('Poore, Jordan'!I$4:I$32,'Poore, Jordan'!$E$4:$E$32,$A7)+SUMIFS('Powers, Dave'!I$4:I$58,'Powers, Dave'!$E$4:$E$58,$A7) -> 0 | F7: =SUMIFS('Barrett, Ken'!J$4:J$31,'Barrett, Ken'!$E$4:$E$31,$A7)+SUMIFS('Brundage, Eric'!J$4:J$39,'Brundage, Eric'!$E$4:$E$39,$A7)+SUMIFS('Dubois, Joe'!J$4:J$70,'Dubois, Joe'!$E$4:$E$70,$A7)+SUMIFS('Gould, Kyle'!J$4:J$53,'Gould, Kyle'!$E$4:$E$53,$A7)+SUMIFS('Jamer, Douglas'!J$4:J$33,'Jamer, Douglas'!$E$4:$E$33,$A7)+SUMIFS('Kennedy, Michael'!J$4:J$87,'Kennedy, Michael'!$E$4:$E$87,$A7)+SUMIFS('Kennedy, Vince'!J$4:J$29,'Kennedy, Vince'!$E$4:$E$29,$A7)+SUMIFS('Morningstar, Jeremy J'!J$4:J$50,'Morningstar, Jeremy J'!$E$4:$E$50,$A7)+SUMIFS('Pendlebury, Jay'!J$4:J$31,'Pendlebury, Jay'!$E$4:$E$31,$A7)+SUMIFS('Poore, Jordan'!J$4:J$32,'Poore, Jordan'!$E$4:$E$32,$A7)+SUMIFS('Powers, Dave'!J$4:J$58,'Powers, Dave'!$E$4:$E$58,$A7) -> 0 | G7: =SUMIFS('Barrett, Ken'!K$4:K$31,'Barrett, Ken'!$E$4:$E$31,$A7)+SUMIFS('Brundage, Eric'!K$4:K$39,'Brundage, Eric'!$E$4:$E$39,$A7)+SUMIFS('Dubois, Joe'!K$4:K$70,'Dubois, Joe'!$E$4:$E$70,$A7)+SUMIFS('Gould, Kyle'!K$4:K$53,'Gould, Kyle'!$E$4:$E$53,$A7)+SUMIFS('Jamer, Douglas'!K$4:K$33,'Jamer, Douglas'!$E$4:$E$33,$A7)+SUMIFS('Kennedy, Michael'!K$4:K$87,'Kennedy, Michael'!$E$4:$E$87,$A7)+SUMIFS('Kennedy, Vince'!K$4:K$29,'Kennedy, Vince'!$E$4:$E$29,$A7)+SUMIFS('Morningstar, Jeremy J'!K$4:K$50,'Morningstar, Jeremy J'!$E$4:$E$50,$A7)+SUMIFS('Pendlebury, Jay'!K$4:K$31,'Pendlebury, Jay'!$E$4:$E$31,$A7)+SUMIFS('Poore, Jordan'!K$4:K$32,'Poore, Jordan'!$E$4:$E$32,$A7)+SUMIFS('Powers, Dave'!K$4:K$58,'Powers, Dave'!$E$4:$E$58,$A7) -> 0 | H7: =SUMIFS('Barrett, Ken'!L$4:L$31,'Barrett, Ken'!$E$4:$E$31,$A7)+SUMIFS('Brundage, Eric'!L$4:L$39,'Brundage, Eric'!$E$4:$E$39,$A7)+SUMIFS('Dubois, Joe'!L$4:L$70,'Dubois, Joe'!$E$4:$E$70,$A7)+SUMIFS('Gould, Kyle'!L$4:L$53,'Gould, Kyle'!$E$4:$E$53,$A7)+SUMIFS('Jamer, Douglas'!L$4:L$33,'Jamer, Douglas'!$E$4:$E$33,$A7)+SUMIFS('Kennedy, Michael'!L$4:L$87,'Kennedy, Michael'!$E$4:$E$87,$A7)+SUMIFS('Kennedy, Vince'!L$4:L$29,'Kennedy, Vince'!$E$4:$E$29,$A7)+SUMIFS('Morningstar, Jeremy J'!L$4:L$50,'Morningstar, Jeremy J'!$E$4:$E$50,$A7)+SUMIFS('Pendlebury, Jay'!L$4:L$31,'Pendlebury, Jay'!$E$4:$E$31,$A7)+SUMIFS('Poore, Jordan'!L$4:L$32,'Poore, Jordan'!$E$4:$E$32,$A7)+SUMIFS('Powers, Dave'!L$4:L$58,'Powers, Dave'!$E$4:$E$58,$A7) -> 0 | I7: =SUMIFS('Barrett, Ken'!M$4:M$31,'Barrett, Ken'!$E$4:$E$31,$A7)+SUMIFS('Brundage, Eric'!M$4:M$39,'Brundage, Eric'!$E$4:$E$39,$A7)+SUMIFS('Dubois, Joe'!M$4:M$70,'Dubois, Joe'!$E$4:$E$70,$A7)+SUMIFS('Gould, Kyle'!M$4:M$53,'Gould, Kyle'!$E$4:$E$53,$A7)+SUMIFS('Jamer, Douglas'!M$4:M$33,'Jamer, Douglas'!$E$4:$E$33,$A7)+SUMIFS('Kennedy, Michael'!M$4:M$87,'Kennedy, Michael'!$E$4:$E$87,$A7)+SUMIFS('Kennedy, Vince'!M$4:M$29,'Kennedy, Vince'!$E$4:$E$29,$A7)+SUMIFS('Morningstar, Jeremy J'!M$4:M$50,'Morningstar, Jeremy J'!$E$4:$E$50,$A7)+SUMIFS('Pendlebury, Jay'!M$4:M$31,'Pendlebury, Jay'!$E$4:$E$31,$A7)+SUMIFS('Poore, Jordan'!M$4:M$32,'Poore, Jordan'!$E$4:$E$32,$A7)+SUMIFS('Powers, Dave'!M$4:M$58,'Powers, Dave'!$E$4:$E$58,$A7) -> 0 | ... S7: =SUMIFS('Barrett, Ken'!W$4:W$31,'Barrett, Ken'!$E$4:$E$31,$A7)+SUMIFS('Brundage, Eric'!W$4:W$39,'Brundage, Eric'!$E$4:$E$39,$A7)+SUMIFS('Dubois, Joe'!W$4:W$70,'Dubois, Joe'!$E$4:$E$70,$A7)+SUMIFS('Gould, Kyle'!W$4:W$53,'Gould, Kyle'!$E$4:$E$53,$A7)+SUMIFS('Jamer, Douglas'!W$4:W$33,'Jamer, Douglas'!$E$4:$E$33,$A7)+SUMIFS('Kennedy, Michael'!W$4:W$87,'Kennedy, Michael'!$E$4:$E$87,$A7)+SUMIFS('Kennedy, Vince'!W$4:W$29,'Kennedy, Vince'!$E$4:$E$29,$A7)+SUMIFS('Morningstar, Jeremy J'!W$4:W$50,'Morningstar, Jeremy J'!$E$4:$E$50,$A7)+SUMIFS('Pendlebury, Jay'!W$4:W$31,'Pendlebury, Jay'!$E$4:$E$31,$A7)+SUMIFS('Poore, Jordan'!W$4:W$32,'Poore, Jordan'!$E$4:$E$32,$A7)+SUMIFS('Powers, Dave'!W$4:W$58,'Powers, Dave'!$E$4:$E$58,$A7) -> 0 | T7: =SUM(B7:S7) -> 0
A8: Ironworker | B8: =SUMIFS('Barrett, Ken'!F$4:F$31,'Barrett, Ken'!$E$4:$E$31,$A8)+SUMIFS('Brundage, Eric'!F$4:F$39,'Brundage, Eric'!$E$4:$E$39,$A8)+SUMIFS('Dubois, Joe'!F$4:F$70,'Dubois, Joe'!$E$4:$E$70,$A8)+SUMIFS('Gould, Kyle'!F$4:F$53,'Gould, Kyle'!$E$4:$E$53,$A8)+SUMIFS('Jamer, Douglas'!F$4:F$33,'Jamer, Douglas'!$E$4:$E$33,$A8)+SUMIFS('Kennedy, Michael'!F$4:F$87,'Kennedy, Michael'!$E$4:$E$87,$A8)+SUMIFS('Kennedy, Vince'!F$4:F$29,'Kennedy, Vince'!$E$4:$E$29,$A8)+SUMIFS('Morningstar, Jeremy J'!F$4:F$50,'Morningstar, Jeremy J'!$E$4:$E$50,$A8)+SUMIFS('Pendlebury, Jay'!F$4:F$31,'Pendlebury, Jay'!$E$4:$E$31,$A8)+SUMIFS('Poore, Jordan'!F$4:F$32,'Poore, Jordan'!$E$4:$E$32,$A8)+SUMIFS('Powers, Dave'!F$4:F$58,'Powers, Dave'!$E$4:$E$58,$A8) -> 0 | C8: =SUMIFS('Barrett, Ken'!G$4:G$31,'Barrett, Ken'!$E$4:$E$31,$A8)+SUMIFS('Brundage, Eric'!G$4:G$39,'Brundage, Eric'!$E$4:$E$39,$A8)+SUMIFS('Dubois, Joe'!G$4:G$70,'Dubois, Joe'!$E$4:$E$70,$A8)+SUMIFS('Gould, Kyle'!G$4:G$53,'Gould, Kyle'!$E$4:$E$53,$A8)+SUMIFS('Jamer, Douglas'!G$4:G$33,'Jamer, Douglas'!$E$4:$E$33,$A8)+SUMIFS('Kennedy, Michael'!G$4:G$87,'Kennedy, Michael'!$E$4:$E$87,$A8)+SUMIFS('Kennedy, Vince'!G$4:G$29,'Kennedy, Vince'!$E$4:$E$29,$A8)+SUMIFS('Morningstar, Jeremy J'!G$4:G$50,'Morningstar, Jeremy J'!$E$4:$E$50,$A8)+SUMIFS('Pendlebury, Jay'!G$4:G$31,'Pendlebury, Jay'!$E$4:$E$31,$A8)+SUMIFS('Poore, Jordan'!G$4:G$32,'Poore, Jordan'!$E$4:$E$32,$A8)+SUMIFS('Powers, Dave'!G$4:G$58,'Powers, Dave'!$E$4:$E$58,$A8) -> 0 | D8: =SUMIFS('Barrett, Ken'!H$4:H$31,'Barrett, Ken'!$E$4:$E$31,$A8)+SUMIFS('Brundage, Eric'!H$4:H$39,'Brundage, Eric'!$E$4:$E$39,$A8)+SUMIFS('Dubois, Joe'!H$4:H$70,'Dubois, Joe'!$E$4:$E$70,$A8)+SUMIFS('Gould, Kyle'!H$4:H$53,'Gould, Kyle'!$E$4:$E$53,$A8)+SUMIFS('Jamer, Douglas'!H$4:H$33,'Jamer, Douglas'!$E$4:$E$33,$A8)+SUMIFS('Kennedy, Michael'!H$4:H$87,'Kennedy, Michael'!$E$4:$E$87,$A8)+SUMIFS('Kennedy, Vince'!H$4:H$29,'Kennedy, Vince'!$E$4:$E$29,$A8)+SUMIFS('Morningstar, Jeremy J'!H$4:H$50,'Morningstar, Jeremy J'!$E$4:$E$50,$A8)+SUMIFS('Pendlebury, Jay'!H$4:H$31,'Pendlebury, Jay'!$E$4:$E$31,$A8)+SUMIFS('Poore, Jordan'!H$4:H$32,'Poore, Jordan'!$E$4:$E$32,$A8)+SUMIFS('Powers, Dave'!H$4:H$58,'Powers, Dave'!$E$4:$E$58,$A8) -> 0 | E8: =SUMIFS('Barrett, Ken'!I$4:I$31,'Barrett, Ken'!$E$4:$E$31,$A8)+SUMIFS('Brundage, Eric'!I$4:I$39,'Brundage, Eric'!$E$4:$E$39,$A8)+SUMIFS('Dubois, Joe'!I$4:I$70,'Dubois, Joe'!$E$4:$E$70,$A8)+SUMIFS('Gould, Kyle'!I$4:I$53,'Gould, Kyle'!$E$4:$E$53,$A8)+SUMIFS('Jamer, Douglas'!I$4:I$33,'Jamer, Douglas'!$E$4:$E$33,$A8)+SUMIFS('Kennedy, Michael'!I$4:I$87,'Kennedy, Michael'!$E$4:$E$87,$A8)+SUMIFS('Kennedy, Vince'!I$4:I$29,'Kennedy, Vince'!$E$4:$E$29,$A8)+SUMIFS('Morningstar, Jeremy J'!I$4:I$50,'Morningstar, Jeremy J'!$E$4:$E$50,$A8)+SUMIFS('Pendlebury, Jay'!I$4:I$31,'Pendlebury, Jay'!$E$4:$E$31,$A8)+SUMIFS('Poore, Jordan'!I$4:I$32,'Poore, Jordan'!$E$4:$E$32,$A8)+SUMIFS('Powers, Dave'!I$4:I$58,'Powers, Dave'!$E$4:$E$58,$A8) -> 0 | F8: =SUMIFS('Barrett, Ken'!J$4:J$31,'Barrett, Ken'!$E$4:$E$31,$A8)+SUMIFS('Brundage, Eric'!J$4:J$39,'Brundage, Eric'!$E$4:$E$39,$A8)+SUMIFS('Dubois, Joe'!J$4:J$70,'Dubois, Joe'!$E$4:$E$70,$A8)+SUMIFS('Gould, Kyle'!J$4:J$53,'Gould, Kyle'!$E$4:$E$53,$A8)+SUMIFS('Jamer, Douglas'!J$4:J$33,'Jamer, Douglas'!$E$4:$E$33,$A8)+SUMIFS('Kennedy, Michael'!J$4:J$87,'Kennedy, Michael'!$E$4:$E$87,$A8)+SUMIFS('Kennedy, Vince'!J$4:J$29,'Kennedy, Vince'!$E$4:$E$29,$A8)+SUMIFS('Morningstar, Jeremy J'!J$4:J$50,'Morningstar, Jeremy J'!$E$4:$E$50,$A8)+SUMIFS('Pendlebury, Jay'!J$4:J$31,'Pendlebury, Jay'!$E$4:$E$31,$A8)+SUMIFS('Poore, Jordan'!J$4:J$32,'Poore, Jordan'!$E$4:$E$32,$A8)+SUMIFS('Powers, Dave'!J$4:J$58,'Powers, Dave'!$E$4:$E$58,$A8) -> 0 | G8: =SUMIFS('Barrett, Ken'!K$4:K$31,'Barrett, Ken'!$E$4:$E$31,$A8)+SUMIFS('Brundage, Eric'!K$4:K$39,'Brundage, Eric'!$E$4:$E$39,$A8)+SUMIFS('Dubois, Joe'!K$4:K$70,'Dubois, Joe'!$E$4:$E$70,$A8)+SUMIFS('Gould, Kyle'!K$4:K$53,'Gould, Kyle'!$E$4:$E$53,$A8)+SUMIFS('Jamer, Douglas'!K$4:K$33,'Jamer, Douglas'!$E$4:$E$33,$A8)+SUMIFS('Kennedy, Michael'!K$4:K$87,'Kennedy, Michael'!$E$4:$E$87,$A8)+SUMIFS('Kennedy, Vince'!K$4:K$29,'Kennedy, Vince'!$E$4:$E$29,$A8)+SUMIFS('Morningstar, Jeremy J'!K$4:K$50,'Morningstar, Jeremy J'!$E$4:$E$50,$A8)+SUMIFS('Pendlebury, Jay'!K$4:K$31,'Pendlebury, Jay'!$E$4:$E$31,$A8)+SUMIFS('Poore, Jordan'!K$4:K$32,'Poore, Jordan'!$E$4:$E$32,$A8)+SUMIFS('Powers, Dave'!K$4:K$58,'Powers, Dave'!$E$4:$E$58,$A8) -> 0 | H8: =SUMIFS('Barrett, Ken'!L$4:L$31,'Barrett, Ken'!$E$4:$E$31,$A8)+SUMIFS('Brundage, Eric'!L$4:L$39,'Brundage, Eric'!$E$4:$E$39,$A8)+SUMIFS('Dubois, Joe'!L$4:L$70,'Dubois, Joe'!$E$4:$E$70,$A8)+SUMIFS('Gould, Kyle'!L$4:L$53,'Gould, Kyle'!$E$4:$E$53,$A8)+SUMIFS('Jamer, Douglas'!L$4:L$33,'Jamer, Douglas'!$E$4:$E$33,$A8)+SUMIFS('Kennedy, Michael'!L$4:L$87,'Kennedy, Michael'!$E$4:$E$87,$A8)+SUMIFS('Kennedy, Vince'!L$4:L$29,'Kennedy, Vince'!$E$4:$E$29,$A8)+SUMIFS('Morningstar, Jeremy J'!L$4:L$50,'Morningstar, Jeremy J'!$E$4:$E$50,$A8)+SUMIFS('Pendlebury, Jay'!L$4:L$31,'Pendlebury, Jay'!$E$4:$E$31,$A8)+SUMIFS('Poore, Jordan'!L$4:L$32,'Poore, Jordan'!$E$4:$E$32,$A8)+SUMIFS('Powers, Dave'!L$4:L$58,'Powers, Dave'!$E$4:$E$58,$A8) -> 0 | I8: =SUMIFS('Barrett, Ken'!M$4:M$31,'Barrett, Ken'!$E$4:$E$31,$A8)+SUMIFS('Brundage, Eric'!M$4:M$39,'Brundage, Eric'!$E$4:$E$39,$A8)+SUMIFS('Dubois, Joe'!M$4:M$70,'Dubois, Joe'!$E$4:$E$70,$A8)+SUMIFS('Gould, Kyle'!M$4:M$53,'Gould, Kyle'!$E$4:$E$53,$A8)+SUMIFS('Jamer, Douglas'!M$4:M$33,'Jamer, Douglas'!$E$4:$E$33,$A8)+SUMIFS('Kennedy, Michael'!M$4:M$87,'Kennedy, Michael'!$E$4:$E$87,$A8)+SUMIFS('Kennedy, Vince'!M$4:M$29,'Kennedy, Vince'!$E$4:$E$29,$A8)+SUMIFS('Morningstar, Jeremy J'!M$4:M$50,'Morningstar, Jeremy J'!$E$4:$E$50,$A8)+SUMIFS('Pendlebury, Jay'!M$4:M$31,'Pendlebury, Jay'!$E$4:$E$31,$A8)+SUMIFS('Poore, Jordan'!M$4:M$32,'Poore, Jordan'!$E$4:$E$32,$A8)+SUMIFS('Powers, Dave'!M$4:M$58,'Powers, Dave'!$E$4:$E$58,$A8) -> 0 | ... S8: =SUMIFS('Barrett, Ken'!W$4:W$31,'Barrett, Ken'!$E$4:$E$31,$A8)+SUMIFS('Brundage, Eric'!W$4:W$39,'Brundage, Eric'!$E$4:$E$39,$A8)+SUMIFS('Dubois, Joe'!W$4:W$70,'Dubois, Joe'!$E$4:$E$70,$A8)+SUMIFS('Gould, Kyle'!W$4:W$53,'Gould, Kyle'!$E$4:$E$53,$A8)+SUMIFS('Jamer, Douglas'!W$4:W$33,'Jamer, Douglas'!$E$4:$E$33,$A8)+SUMIFS('Kennedy, Michael'!W$4:W$87,'Kennedy, Michael'!$E$4:$E$87,$A8)+SUMIFS('Kennedy, Vince'!W$4:W$29,'Kennedy, Vince'!$E$4:$E$29,$A8)+SUMIFS('Morningstar, Jeremy J'!W$4:W$50,'Morningstar, Jeremy J'!$E$4:$E$50,$A8)+SUMIFS('Pendlebury, Jay'!W$4:W$31,'Pendlebury, Jay'!$E$4:$E$31,$A8)+SUMIFS('Poore, Jordan'!W$4:W$32,'Poore, Jordan'!$E$4:$E$32,$A8)+SUMIFS('Powers, Dave'!W$4:W$58,'Powers, Dave'!$E$4:$E$58,$A8) -> 0 | T8: =SUM(B8:S8) -> 0
A9: Electrician | B9: =SUMIFS('Barrett, Ken'!F$4:F$31,'Barrett, Ken'!$E$4:$E$31,$A9)+SUMIFS('Brundage, Eric'!F$4:F$39,'Brundage, Eric'!$E$4:$E$39,$A9)+SUMIFS('Dubois, Joe'!F$4:F$70,'Dubois, Joe'!$E$4:$E$70,$A9)+SUMIFS('Gould, Kyle'!F$4:F$53,'Gould, Kyle'!$E$4:$E$53,$A9)+SUMIFS('Jamer, Douglas'!F$4:F$33,'Jamer, Douglas'!$E$4:$E$33,$A9)+SUMIFS('Kennedy, Michael'!F$4:F$87,'Kennedy, Michael'!$E$4:$E$87,$A9)+SUMIFS('Kennedy, Vince'!F$4:F$29,'Kennedy, Vince'!$E$4:$E$29,$A9)+SUMIFS('Morningstar, Jeremy J'!F$4:F$50,'Morningstar, Jeremy J'!$E$4:$E$50,$A9)+SUMIFS('Pendlebury, Jay'!F$4:F$31,'Pendlebury, Jay'!$E$4:$E$31,$A9)+SUMIFS('Poore, Jordan'!F$4:F$32,'Poore, Jordan'!$E$4:$E$32,$A9)+SUMIFS('Powers, Dave'!F$4:F$58,'Powers, Dave'!$E$4:$E$58,$A9) -> 0 | C9: =SUMIFS('Barrett, Ken'!G$4:G$31,'Barrett, Ken'!$E$4:$E$31,$A9)+SUMIFS('Brundage, Eric'!G$4:G$39,'Brundage, Eric'!$E$4:$E$39,$A9)+SUMIFS('Dubois, Joe'!G$4:G$70,'Dubois, Joe'!$E$4:$E$70,$A9)+SUMIFS('Gould, Kyle'!G$4:G$53,'Gould, Kyle'!$E$4:$E$53,$A9)+SUMIFS('Jamer, Douglas'!G$4:G$33,'Jamer, Douglas'!$E$4:$E$33,$A9)+SUMIFS('Kennedy, Michael'!G$4:G$87,'Kennedy, Michael'!$E$4:$E$87,$A9)+SUMIFS('Kennedy, Vince'!G$4:G$29,'Kennedy, Vince'!$E$4:$E$29,$A9)+SUMIFS('Morningstar, Jeremy J'!G$4:G$50,'Morningstar, Jeremy J'!$E$4:$E$50,$A9)+SUMIFS('Pendlebury, Jay'!G$4:G$31,'Pendlebury, Jay'!$E$4:$E$31,$A9)+SUMIFS('Poore, Jordan'!G$4:G$32,'Poore, Jordan'!$E$4:$E$32,$A9)+SUMIFS('Powers, Dave'!G$4:G$58,'Powers, Dave'!$E$4:$E$58,$A9) -> 0 | D9: =SUMIFS('Barrett, Ken'!H$4:H$31,'Barrett, Ken'!$E$4:$E$31,$A9)+SUMIFS('Brundage, Eric'!H$4:H$39,'Brundage, Eric'!$E$4:$E$39,$A9)+SUMIFS('Dubois, Joe'!H$4:H$70,'Dubois, Joe'!$E$4:$E$70,$A9)+SUMIFS('Gould, Kyle'!H$4:H$53,'Gould, Kyle'!$E$4:$E$53,$A9)+SUMIFS('Jamer, Douglas'!H$4:H$33,'Jamer, Douglas'!$E$4:$E$33,$A9)+SUMIFS('Kennedy, Michael'!H$4:H$87,'Kennedy, Michael'!$E$4:$E$87,$A9)+SUMIFS('Kennedy, Vince'!H$4:H$29,'Kennedy, Vince'!$E$4:$E$29,$A9)+SUMIFS('Morningstar, Jeremy J'!H$4:H$50,'Morningstar, Jeremy J'!$E$4:$E$50,$A9)+SUMIFS('Pendlebury, Jay'!H$4:H$31,'Pendlebury, Jay'!$E$4:$E$31,$A9)+SUMIFS('Poore, Jordan'!H$4:H$32,'Poore, Jordan'!$E$4:$E$32,$A9)+SUMIFS('Powers, Dave'!H$4:H$58,'Powers, Dave'!$E$4:$E$58,$A9) -> 0 | E9: =SUMIFS('Barrett, Ken'!I$4:I$31,'Barrett, Ken'!$E$4:$E$31,$A9)+SUMIFS('Brundage, Eric'!I$4:I$39,'Brundage, Eric'!$E$4:$E$39,$A9)+SUMIFS('Dubois, Joe'!I$4:I$70,'Dubois, Joe'!$E$4:$E$70,$A9)+SUMIFS('Gould, Kyle'!I$4:I$53,'Gould, Kyle'!$E$4:$E$53,$A9)+SUMIFS('Jamer, Douglas'!I$4:I$33,'Jamer, Douglas'!$E$4:$E$33,$A9)+SUMIFS('Kennedy, Michael'!I$4:I$87,'Kennedy, Michael'!$E$4:$E$87,$A9)+SUMIFS('Kennedy, Vince'!I$4:I$29,'Kennedy, Vince'!$E$4:$E$29,$A9)+SUMIFS('Morningstar, Jeremy J'!I$4:I$50,'Morningstar, Jeremy J'!$E$4:$E$50,$A9)+SUMIFS('Pendlebury, Jay'!I$4:I$31,'Pendlebury, Jay'!$E$4:$E$31,$A9)+SUMIFS('Poore, Jordan'!I$4:I$32,'Poore, Jordan'!$E$4:$E$32,$A9)+SUMIFS('Powers, Dave'!I$4:I$58,'Powers, Dave'!$E$4:$E$58,$A9) -> 0 | F9: =SUMIFS('Barrett, Ken'!J$4:J$31,'Barrett, Ken'!$E$4:$E$31,$A9)+SUMIFS('Brundage, Eric'!J$4:J$39,'Brundage, Eric'!$E$4:$E$39,$A9)+SUMIFS('Dubois, Joe'!J$4:J$70,'Dubois, Joe'!$E$4:$E$70,$A9)+SUMIFS('Gould, Kyle'!J$4:J$53,'Gould, Kyle'!$E$4:$E$53,$A9)+SUMIFS('Jamer, Douglas'!J$4:J$33,'Jamer, Douglas'!$E$4:$E$33,$A9)+SUMIFS('Kennedy, Michael'!J$4:J$87,'Kennedy, Michael'!$E$4:$E$87,$A9)+SUMIFS('Kennedy, Vince'!J$4:J$29,'Kennedy, Vince'!$E$4:$E$29,$A9)+SUMIFS('Morningstar, Jeremy J'!J$4:J$50,'Morningstar, Jeremy J'!$E$4:$E$50,$A9)+SUMIFS('Pendlebury, Jay'!J$4:J$31,'Pendlebury, Jay'!$E$4:$E$31,$A9)+SUMIFS('Poore, Jordan'!J$4:J$32,'Poore, Jordan'!$E$4:$E$32,$A9)+SUMIFS('Powers, Dave'!J$4:J$58,'Powers, Dave'!$E$4:$E$58,$A9) -> 0 | G9: =SUMIFS('Barrett, Ken'!K$4:K$31,'Barrett, Ken'!$E$4:$E$31,$A9)+SUMIFS('Brundage, Eric'!K$4:K$39,'Brundage, Eric'!$E$4:$E$39,$A9)+SUMIFS('Dubois, Joe'!K$4:K$70,'Dubois, Joe'!$E$4:$E$70,$A9)+SUMIFS('Gould, Kyle'!K$4:K$53,'Gould, Kyle'!$E$4:$E$53,$A9)+SUMIFS('Jamer, Douglas'!K$4:K$33,'Jamer, Douglas'!$E$4:$E$33,$A9)+SUMIFS('Kennedy, Michael'!K$4:K$87,'Kennedy, Michael'!$E$4:$E$87,$A9)+SUMIFS('Kennedy, Vince'!K$4:K$29,'Kennedy, Vince'!$E$4:$E$29,$A9)+SUMIFS('Morningstar, Jeremy J'!K$4:K$50,'Morningstar, Jeremy J'!$E$4:$E$50,$A9)+SUMIFS('Pendlebury, Jay'!K$4:K$31,'Pendlebury, Jay'!$E$4:$E$31,$A9)+SUMIFS('Poore, Jordan'!K$4:K$32,'Poore, Jordan'!$E$4:$E$32,$A9)+SUMIFS('Powers, Dave'!K$4:K$58,'Powers, Dave'!$E$4:$E$58,$A9) -> 0 | H9: =SUMIFS('Barrett, Ken'!L$4:L$31,'Barrett, Ken'!$E$4:$E$31,$A9)+SUMIFS('Brundage, Eric'!L$4:L$39,'Brundage, Eric'!$E$4:$E$39,$A9)+SUMIFS('Dubois, Joe'!L$4:L$70,'Dubois, Joe'!$E$4:$E$70,$A9)+SUMIFS('Gould, Kyle'!L$4:L$53,'Gould, Kyle'!$E$4:$E$53,$A9)+SUMIFS('Jamer, Douglas'!L$4:L$33,'Jamer, Douglas'!$E$4:$E$33,$A9)+SUMIFS('Kennedy, Michael'!L$4:L$87,'Kennedy, Michael'!$E$4:$E$87,$A9)+SUMIFS('Kennedy, Vince'!L$4:L$29,'Kennedy, Vince'!$E$4:$E$29,$A9)+SUMIFS('Morningstar, Jeremy J'!L$4:L$50,'Morningstar, Jeremy J'!$E$4:$E$50,$A9)+SUMIFS('Pendlebury, Jay'!L$4:L$31,'Pendlebury, Jay'!$E$4:$E$31,$A9)+SUMIFS('Poore, Jordan'!L$4:L$32,'Poore, Jordan'!$E$4:$E$32,$A9)+SUMIFS('Powers, Dave'!L$4:L$58,'Powers, Dave'!$E$4:$E$58,$A9) -> 0 | I9: =SUMIFS('Barrett, Ken'!M$4:M$31,'Barrett, Ken'!$E$4:$E$31,$A9)+SUMIFS('Brundage, Eric'!M$4:M$39,'Brundage, Eric'!$E$4:$E$39,$A9)+SUMIFS('Dubois, Joe'!M$4:M$70,'Dubois, Joe'!$E$4:$E$70,$A9)+SUMIFS('Gould, Kyle'!M$4:M$53,'Gould, Kyle'!$E$4:$E$53,$A9)+SUMIFS('Jamer, Douglas'!M$4:M$33,'Jamer, Douglas'!$E$4:$E$33,$A9)+SUMIFS('Kennedy, Michael'!M$4:M$87,'Kennedy, Michael'!$E$4:$E$87,$A9)+SUMIFS('Kennedy, Vince'!M$4:M$29,'Kennedy, Vince'!$E$4:$E$29,$A9)+SUMIFS('Morningstar, Jeremy J'!M$4:M$50,'Morningstar, Jeremy J'!$E$4:$E$50,$A9)+SUMIFS('Pendlebury, Jay'!M$4:M$31,'Pendlebury, Jay'!$E$4:$E$31,$A9)+SUMIFS('Poore, Jordan'!M$4:M$32,'Poore, Jordan'!$E$4:$E$32,$A9)+SUMIFS('Powers, Dave'!M$4:M$58,'Powers, Dave'!$E$4:$E$58,$A9) -> 0 | ... S9: =SUMIFS('Barrett, Ken'!W$4:W$31,'Barrett, Ken'!$E$4:$E$31,$A9)+SUMIFS('Brundage, Eric'!W$4:W$39,'Brundage, Eric'!$E$4:$E$39,$A9)+SUMIFS('Dubois, Joe'!W$4:W$70,'Dubois, Joe'!$E$4:$E$70,$A9)+SUMIFS('Gould, Kyle'!W$4:W$53,'Gould, Kyle'!$E$4:$E$53,$A9)+SUMIFS('Jamer, Douglas'!W$4:W$33,'Jamer, Douglas'!$E$4:$E$33,$A9)+SUMIFS('Kennedy, Michael'!W$4:W$87,'Kennedy, Michael'!$E$4:$E$87,$A9)+SUMIFS('Kennedy, Vince'!W$4:W$29,'Kennedy, Vince'!$E$4:$E$29,$A9)+SUMIFS('Morningstar, Jeremy J'!W$4:W$50,'Morningstar, Jeremy J'!$E$4:$E$50,$A9)+SUMIFS('Pendlebury, Jay'!W$4:W$31,'Pendlebury, Jay'!$E$4:$E$31,$A9)+SUMIFS('Poore, Jordan'!W$4:W$32,'Poore, Jordan'!$E$4:$E$32,$A9)+SUMIFS('Powers, Dave'!W$4:W$58,'Powers, Dave'!$E$4:$E$58,$A9) -> 0 | T9: =SUM(B9:S9) -> 0
A10: Instrumentation | B10: =SUMIFS('Barrett, Ken'!F$4:F$31,'Barrett, Ken'!$E$4:$E$31,$A10)+SUMIFS('Brundage, Eric'!F$4:F$39,'Brundage, Eric'!$E$4:$E$39,$A10)+SUMIFS('Dubois, Joe'!F$4:F$70,'Dubois, Joe'!$E$4:$E$70,$A10)+SUMIFS('Gould, Kyle'!F$4:F$53,'Gould, Kyle'!$E$4:$E$53,$A10)+SUMIFS('Jamer, Douglas'!F$4:F$33,'Jamer, Douglas'!$E$4:$E$33,$A10)+SUMIFS('Kennedy, Michael'!F$4:F$87,'Kennedy, Michael'!$E$4:$E$87,$A10)+SUMIFS('Kennedy, Vince'!F$4:F$29,'Kennedy, Vince'!$E$4:$E$29,$A10)+SUMIFS('Morningstar, Jeremy J'!F$4:F$50,'Morningstar, Jeremy J'!$E$4:$E$50,$A10)+SUMIFS('Pendlebury, Jay'!F$4:F$31,'Pendlebury, Jay'!$E$4:$E$31,$A10)+SUMIFS('Poore, Jordan'!F$4:F$32,'Poore, Jordan'!$E$4:$E$32,$A10)+SUMIFS('Powers, Dave'!F$4:F$58,'Powers, Dave'!$E$4:$E$58,$A10) -> 0 | C10: =SUMIFS('Barrett, Ken'!G$4:G$31,'Barrett, Ken'!$E$4:$E$31,$A10)+SUMIFS('Brundage, Eric'!G$4:G$39,'Brundage, Eric'!$E$4:$E$39,$A10)+SUMIFS('Dubois, Joe'!G$4:G$70,'Dubois, Joe'!$E$4:$E$70,$A10)+SUMIFS('Gould, Kyle'!G$4:G$53,'Gould, Kyle'!$E$4:$E$53,$A10)+SUMIFS('Jamer, Douglas'!G$4:G$33,'Jamer, Douglas'!$E$4:$E$33,$A10)+SUMIFS('Kennedy, Michael'!G$4:G$87,'Kennedy, Michael'!$E$4:$E$87,$A10)+SUMIFS('Kennedy, Vince'!G$4:G$29,'Kennedy, Vince'!$E$4:$E$29,$A10)+SUMIFS('Morningstar, Jeremy J'!G$4:G$50,'Morningstar, Jeremy J'!$E$4:$E$50,$A10)+SUMIFS('Pendlebury, Jay'!G$4:G$31,'Pendlebury, Jay'!$E$4:$E$31,$A10)+SUMIFS('Poore, Jordan'!G$4:G$32,'Poore, Jordan'!$E$4:$E$32,$A10)+SUMIFS('Powers, Dave'!G$4:G$58,'Powers, Dave'!$E$4:$E$58,$A10) -> 0 | D10: =SUMIFS('Barrett, Ken'!H$4:H$31,'Barrett, Ken'!$E$4:$E$31,$A10)+SUMIFS('Brundage, Eric'!H$4:H$39,'Brundage, Eric'!$E$4:$E$39,$A10)+SUMIFS('Dubois, Joe'!H$4:H$70,'Dubois, Joe'!$E$4:$E$70,$A10)+SUMIFS('Gould, Kyle'!H$4:H$53,'Gould, Kyle'!$E$4:$E$53,$A10)+SUMIFS('Jamer, Douglas'!H$4:H$33,'Jamer, Douglas'!$E$4:$E$33,$A10)+SUMIFS('Kennedy, Michael'!H$4:H$87,'Kennedy, Michael'!$E$4:$E$87,$A10)+SUMIFS('Kennedy, Vince'!H$4:H$29,'Kennedy, Vince'!$E$4:$E$29,$A10)+SUMIFS('Morningstar, Jeremy J'!H$4:H$50,'Morningstar, Jeremy J'!$E$4:$E$50,$A10)+SUMIFS('Pendlebury, Jay'!H$4:H$31,'Pendlebury, Jay'!$E$4:$E$31,$A10)+SUMIFS('Poore, Jordan'!H$4:H$32,'Poore, Jordan'!$E$4:$E$32,$A10)+SUMIFS('Powers, Dave'!H$4:H$58,'Powers, Dave'!$E$4:$E$58,$A10) -> 0 | E10: =SUMIFS('Barrett, Ken'!I$4:I$31,'Barrett, Ken'!$E$4:$E$31,$A10)+SUMIFS('Brundage, Eric'!I$4:I$39,'Brundage, Eric'!$E$4:$E$39,$A10)+SUMIFS('Dubois, Joe'!I$4:I$70,'Dubois, Joe'!$E$4:$E$70,$A10)+SUMIFS('Gould, Kyle'!I$4:I$53,'Gould, Kyle'!$E$4:$E$53,$A10)+SUMIFS('Jamer, Douglas'!I$4:I$33,'Jamer, Douglas'!$E$4:$E$33,$A10)+SUMIFS('Kennedy, Michael'!I$4:I$87,'Kennedy, Michael'!$E$4:$E$87,$A10)+SUMIFS('Kennedy, Vince'!I$4:I$29,'Kennedy, Vince'!$E$4:$E$29,$A10)+SUMIFS('Morningstar, Jeremy J'!I$4:I$50,'Morningstar, Jeremy J'!$E$4:$E$50,$A10)+SUMIFS('Pendlebury, Jay'!I$4:I$31,'Pendlebury, Jay'!$E$4:$E$31,$A10)+SUMIFS('Poore, Jordan'!I$4:I$32,'Poore, Jordan'!$E$4:$E$32,$A10)+SUMIFS('Powers, Dave'!I$4:I$58,'Powers, Dave'!$E$4:$E$58,$A10) -> 0 | F10: =SUMIFS('Barrett, Ken'!J$4:J$31,'Barrett, Ken'!$E$4:$E$31,$A10)+SUMIFS('Brundage, Eric'!J$4:J$39,'Brundage, Eric'!$E$4:$E$39,$A10)+SUMIFS('Dubois, Joe'!J$4:J$70,'Dubois, Joe'!$E$4:$E$70,$A10)+SUMIFS('Gould, Kyle'!J$4:J$53,'Gould, Kyle'!$E$4:$E$53,$A10)+SUMIFS('Jamer, Douglas'!J$4:J$33,'Jamer, Douglas'!$E$4:$E$33,$A10)+SUMIFS('Kennedy, Michael'!J$4:J$87,'Kennedy, Michael'!$E$4:$E$87,$A10)+SUMIFS('Kennedy, Vince'!J$4:J$29,'Kennedy, Vince'!$E$4:$E$29,$A10)+SUMIFS('Morningstar, Jeremy J'!J$4:J$50,'Morningstar, Jeremy J'!$E$4:$E$50,$A10)+SUMIFS('Pendlebury, Jay'!J$4:J$31,'Pendlebury, Jay'!$E$4:$E$31,$A10)+SUMIFS('Poore, Jordan'!J$4:J$32,'Poore, Jordan'!$E$4:$E$32,$A10)+SUMIFS('Powers, Dave'!J$4:J$58,'Powers, Dave'!$E$4:$E$58,$A10) -> 0 | G10: =SUMIFS('Barrett, Ken'!K$4:K$31,'Barrett, Ken'!$E$4:$E$31,$A10)+SUMIFS('Brundage, Eric'!K$4:K$39,'Brundage, Eric'!$E$4:$E$39,$A10)+SUMIFS('Dubois, Joe'!K$4:K$70,'Dubois, Joe'!$E$4:$E$70,$A10)+SUMIFS('Gould, Kyle'!K$4:K$53,'Gould, Kyle'!$E$4:$E$53,$A10)+SUMIFS('Jamer, Douglas'!K$4:K$33,'Jamer, Douglas'!$E$4:$E$33,$A10)+SUMIFS('Kennedy, Michael'!K$4:K$87,'Kennedy, Michael'!$E$4:$E$87,$A10)+SUMIFS('Kennedy, Vince'!K$4:K$29,'Kennedy, Vince'!$E$4:$E$29,$A10)+SUMIFS('Morningstar, Jeremy J'!K$4:K$50,'Morningstar, Jeremy J'!$E$4:$E$50,$A10)+SUMIFS('Pendlebury, Jay'!K$4:K$31,'Pendlebury, Jay'!$E$4:$E$31,$A10)+SUMIFS('Poore, Jordan'!K$4:K$32,'Poore, Jordan'!$E$4:$E$32,$A10)+SUMIFS('Powers, Dave'!K$4:K$58,'Powers, Dave'!$E$4:$E$58,$A10) -> 0 | H10: =SUMIFS('Barrett, Ken'!L$4:L$31,'Barrett, Ken'!$E$4:$E$31,$A10)+SUMIFS('Brundage, Eric'!L$4:L$39,'Brundage, Eric'!$E$4:$E$39,$A10)+SUMIFS('Dubois, Joe'!L$4:L$70,'Dubois, Joe'!$E$4:$E$70,$A10)+SUMIFS('Gould, Kyle'!L$4:L$53,'Gould, Kyle'!$E$4:$E$53,$A10)+SUMIFS('Jamer, Douglas'!L$4:L$33,'Jamer, Douglas'!$E$4:$E$33,$A10)+SUMIFS('Kennedy, Michael'!L$4:L$87,'Kennedy, Michael'!$E$4:$E$87,$A10)+SUMIFS('Kennedy, Vince'!L$4:L$29,'Kennedy, Vince'!$E$4:$E$29,$A10)+SUMIFS('Morningstar, Jeremy J'!L$4:L$50,'Morningstar, Jeremy J'!$E$4:$E$50,$A10)+SUMIFS('Pendlebury, Jay'!L$4:L$31,'Pendlebury, Jay'!$E$4:$E$31,$A10)+SUMIFS('Poore, Jordan'!L$4:L$32,'Poore, Jordan'!$E$4:$E$32,$A10)+SUMIFS('Powers, Dave'!L$4:L$58,'Powers, Dave'!$E$4:$E$58,$A10) -> 0 | I10: =SUMIFS('Barrett, Ken'!M$4:M$31,'Barrett, Ken'!$E$4:$E$31,$A10)+SUMIFS('Brundage, Eric'!M$4:M$39,'Brundage, Eric'!$E$4:$E$39,$A10)+SUMIFS('Dubois, Joe'!M$4:M$70,'Dubois, Joe'!$E$4:$E$70,$A10)+SUMIFS('Gould, Kyle'!M$4:M$53,'Gould, Kyle'!$E$4:$E$53,$A10)+SUMIFS('Jamer, Douglas'!M$4:M$33,'Jamer, Douglas'!$E$4:$E$33,$A10)+SUMIFS('Kennedy, Michael'!M$4:M$87,'Kennedy, Michael'!$E$4:$E$87,$A10)+SUMIFS('Kennedy, Vince'!M$4:M$29,'Kennedy, Vince'!$E$4:$E$29,$A10)+SUMIFS('Morningstar, Jeremy J'!M$4:M$50,'Morningstar, Jeremy J'!$E$4:$E$50,$A10)+SUMIFS('Pendlebury, Jay'!M$4:M$31,'Pendlebury, Jay'!$E$4:$E$31,$A10)+SUMIFS('Poore, Jordan'!M$4:M$32,'Poore, Jordan'!$E$4:$E$32,$A10)+SUMIFS('Powers, Dave'!M$4:M$58,'Powers, Dave'!$E$4:$E$58,$A10) -> 0 | ... S10: =SUMIFS('Barrett, Ken'!W$4:W$31,'Barrett, Ken'!$E$4:$E$31,$A10)+SUMIFS('Brundage, Eric'!W$4:W$39,'Brundage, Eric'!$E$4:$E$39,$A10)+SUMIFS('Dubois, Joe'!W$4:W$70,'Dubois, Joe'!$E$4:$E$70,$A10)+SUMIFS('Gould, Kyle'!W$4:W$53,'Gould, Kyle'!$E$4:$E$53,$A10)+SUMIFS('Jamer, Douglas'!W$4:W$33,'Jamer, Douglas'!$E$4:$E$33,$A10)+SUMIFS('Kennedy, Michael'!W$4:W$87,'Kennedy, Michael'!$E$4:$E$87,$A10)+SUMIFS('Kennedy, Vince'!W$4:W$29,'Kennedy, Vince'!$E$4:$E$29,$A10)+SUMIFS('Morningstar, Jeremy J'!W$4:W$50,'Morningstar, Jeremy J'!$E$4:$E$50,$A10)+SUMIFS('Pendlebury, Jay'!W$4:W$31,'Pendlebury, Jay'!$E$4:$E$31,$A10)+SUMIFS('Poore, Jordan'!W$4:W$32,'Poore, Jordan'!$E$4:$E$32,$A10)+SUMIFS('Powers, Dave'!W$4:W$58,'Powers, Dave'!$E$4:$E$58,$A10) -> 0 | T10: =SUM(B10:S10) -> 0
A11: Insulator | B11: =SUMIFS('Barrett, Ken'!F$4:F$31,'Barrett, Ken'!$E$4:$E$31,$A11)+SUMIFS('Brundage, Eric'!F$4:F$39,'Brundage, Eric'!$E$4:$E$39,$A11)+SUMIFS('Dubois, Joe'!F$4:F$70,'Dubois, Joe'!$E$4:$E$70,$A11)+SUMIFS('Gould, Kyle'!F$4:F$53,'Gould, Kyle'!$E$4:$E$53,$A11)+SUMIFS('Jamer, Douglas'!F$4:F$33,'Jamer, Douglas'!$E$4:$E$33,$A11)+SUMIFS('Kennedy, Michael'!F$4:F$87,'Kennedy, Michael'!$E$4:$E$87,$A11)+SUMIFS('Kennedy, Vince'!F$4:F$29,'Kennedy, Vince'!$E$4:$E$29,$A11)+SUMIFS('Morningstar, Jeremy J'!F$4:F$50,'Morningstar, Jeremy J'!$E$4:$E$50,$A11)+SUMIFS('Pendlebury, Jay'!F$4:F$31,'Pendlebury, Jay'!$E$4:$E$31,$A11)+SUMIFS('Poore, Jordan'!F$4:F$32,'Poore, Jordan'!$E$4:$E$32,$A11)+SUMIFS('Powers, Dave'!F$4:F$58,'Powers, Dave'!$E$4:$E$58,$A11) -> 0 | C11: =SUMIFS('Barrett, Ken'!G$4:G$31,'Barrett, Ken'!$E$4:$E$31,$A11)+SUMIFS('Brundage, Eric'!G$4:G$39,'Brundage, Eric'!$E$4:$E$39,$A11)+SUMIFS('Dubois, Joe'!G$4:G$70,'Dubois, Joe'!$E$4:$E$70,$A11)+SUMIFS('Gould, Kyle'!G$4:G$53,'Gould, Kyle'!$E$4:$E$53,$A11)+SUMIFS('Jamer, Douglas'!G$4:G$33,'Jamer, Douglas'!$E$4:$E$33,$A11)+SUMIFS('Kennedy, Michael'!G$4:G$87,'Kennedy, Michael'!$E$4:$E$87,$A11)+SUMIFS('Kennedy, Vince'!G$4:G$29,'Kennedy, Vince'!$E$4:$E$29,$A11)+SUMIFS('Morningstar, Jeremy J'!G$4:G$50,'Morningstar, Jeremy J'!$E$4:$E$50,$A11)+SUMIFS('Pendlebury, Jay'!G$4:G$31,'Pendlebury, Jay'!$E$4:$E$31,$A11)+SUMIFS('Poore, Jordan'!G$4:G$32,'Poore, Jordan'!$E$4:$E$32,$A11)+SUMIFS('Powers, Dave'!G$4:G$58,'Powers, Dave'!$E$4:$E$58,$A11) -> 0 | D11: =SUMIFS('Barrett, Ken'!H$4:H$31,'Barrett, Ken'!$E$4:$E$31,$A11)+SUMIFS('Brundage, Eric'!H$4:H$39,'Brundage, Eric'!$E$4:$E$39,$A11)+SUMIFS('Dubois, Joe'!H$4:H$70,'Dubois, Joe'!$E$4:$E$70,$A11)+SUMIFS('Gould, Kyle'!H$4:H$53,'Gould, Kyle'!$E$4:$E$53,$A11)+SUMIFS('Jamer, Douglas'!H$4:H$33,'Jamer, Douglas'!$E$4:$E$33,$A11)+SUMIFS('Kennedy, Michael'!H$4:H$87,'Kennedy, Michael'!$E$4:$E$87,$A11)+SUMIFS('Kennedy, Vince'!H$4:H$29,'Kennedy, Vince'!$E$4:$E$29,$A11)+SUMIFS('Morningstar, Jeremy J'!H$4:H$50,'Morningstar, Jeremy J'!$E$4:$E$50,$A11)+SUMIFS('Pendlebury, Jay'!H$4:H$31,'Pendlebury, Jay'!$E$4:$E$31,$A11)+SUMIFS('Poore, Jordan'!H$4:H$32,'Poore, Jordan'!$E$4:$E$32,$A11)+SUMIFS('Powers, Dave'!H$4:H$58,'Powers, Dave'!$E$4:$E$58,$A11) -> 0 | E11: =SUMIFS('Barrett, Ken'!I$4:I$31,'Barrett, Ken'!$E$4:$E$31,$A11)+SUMIFS('Brundage, Eric'!I$4:I$39,'Brundage, Eric'!$E$4:$E$39,$A11)+SUMIFS('Dubois, Joe'!I$4:I$70,'Dubois, Joe'!$E$4:$E$70,$A11)+SUMIFS('Gould, Kyle'!I$4:I$53,'Gould, Kyle'!$E$4:$E$53,$A11)+SUMIFS('Jamer, Douglas'!I$4:I$33,'Jamer, Douglas'!$E$4:$E$33,$A11)+SUMIFS('Kennedy, Michael'!I$4:I$87,'Kennedy, Michael'!$E$4:$E$87,$A11)+SUMIFS('Kennedy, Vince'!I$4:I$29,'Kennedy, Vince'!$E$4:$E$29,$A11)+SUMIFS('Morningstar, Jeremy J'!I$4:I$50,'Morningstar, Jeremy J'!$E$4:$E$50,$A11)+SUMIFS('Pendlebury, Jay'!I$4:I$31,'Pendlebury, Jay'!$E$4:$E$31,$A11)+SUMIFS('Poore, Jordan'!I$4:I$32,'Poore, Jordan'!$E$4:$E$32,$A11)+SUMIFS('Powers, Dave'!I$4:I$58,'Powers, Dave'!$E$4:$E$58,$A11) -> 0 | F11: =SUMIFS('Barrett, Ken'!J$4:J$31,'Barrett, Ken'!$E$4:$E$31,$A11)+SUMIFS('Brundage, Eric'!J$4:J$39,'Brundage, Eric'!$E$4:$E$39,$A11)+SUMIFS('Dubois, Joe'!J$4:J$70,'Dubois, Joe'!$E$4:$E$70,$A11)+SUMIFS('Gould, Kyle'!J$4:J$53,'Gould, Kyle'!$E$4:$E$53,$A11)+SUMIFS('Jamer, Douglas'!J$4:J$33,'Jamer, Douglas'!$E$4:$E$33,$A11)+SUMIFS('Kennedy, Michael'!J$4:J$87,'Kennedy, Michael'!$E$4:$E$87,$A11)+SUMIFS('Kennedy, Vince'!J$4:J$29,'Kennedy, Vince'!$E$4:$E$29,$A11)+SUMIFS('Morningstar, Jeremy J'!J$4:J$50,'Morningstar, Jeremy J'!$E$4:$E$50,$A11)+SUMIFS('Pendlebury, Jay'!J$4:J$31,'Pendlebury, Jay'!$E$4:$E$31,$A11)+SUMIFS('Poore, Jordan'!J$4:J$32,'Poore, Jordan'!$E$4:$E$32,$A11)+SUMIFS('Powers, Dave'!J$4:J$58,'Powers, Dave'!$E$4:$E$58,$A11) -> 0 | G11: =SUMIFS('Barrett, Ken'!K$4:K$31,'Barrett, Ken'!$E$4:$E$31,$A11)+SUMIFS('Brundage, Eric'!K$4:K$39,'Brundage, Eric'!$E$4:$E$39,$A11)+SUMIFS('Dubois, Joe'!K$4:K$70,'Dubois, Joe'!$E$4:$E$70,$A11)+SUMIFS('Gould, Kyle'!K$4:K$53,'Gould, Kyle'!$E$4:$E$53,$A11)+SUMIFS('Jamer, Douglas'!K$4:K$33,'Jamer, Douglas'!$E$4:$E$33,$A11)+SUMIFS('Kennedy, Michael'!K$4:K$87,'Kennedy, Michael'!$E$4:$E$87,$A11)+SUMIFS('Kennedy, Vince'!K$4:K$29,'Kennedy, Vince'!$E$4:$E$29,$A11)+SUMIFS('Morningstar, Jeremy J'!K$4:K$50,'Morningstar, Jeremy J'!$E$4:$E$50,$A11)+SUMIFS('Pendlebury, Jay'!K$4:K$31,'Pendlebury, Jay'!$E$4:$E$31,$A11)+SUMIFS('Poore, Jordan'!K$4:K$32,'Poore, Jordan'!$E$4:$E$32,$A11)+SUMIFS('Powers, Dave'!K$4:K$58,'Powers, Dave'!$E$4:$E$58,$A11) -> 0 | H11: =SUMIFS('Barrett, Ken'!L$4:L$31,'Barrett, Ken'!$E$4:$E$31,$A11)+SUMIFS('Brundage, Eric'!L$4:L$39,'Brundage, Eric'!$E$4:$E$39,$A11)+SUMIFS('Dubois, Joe'!L$4:L$70,'Dubois, Joe'!$E$4:$E$70,$A11)+SUMIFS('Gould, Kyle'!L$4:L$53,'Gould, Kyle'!$E$4:$E$53,$A11)+SUMIFS('Jamer, Douglas'!L$4:L$33,'Jamer, Douglas'!$E$4:$E$33,$A11)+SUMIFS('Kennedy, Michael'!L$4:L$87,'Kennedy, Michael'!$E$4:$E$87,$A11)+SUMIFS('Kennedy, Vince'!L$4:L$29,'Kennedy, Vince'!$E$4:$E$29,$A11)+SUMIFS('Morningstar, Jeremy J'!L$4:L$50,'Morningstar, Jeremy J'!$E$4:$E$50,$A11)+SUMIFS('Pendlebury, Jay'!L$4:L$31,'Pendlebury, Jay'!$E$4:$E$31,$A11)+SUMIFS('Poore, Jordan'!L$4:L$32,'Poore, Jordan'!$E$4:$E$32,$A11)+SUMIFS('Powers, Dave'!L$4:L$58,'Powers, Dave'!$E$4:$E$58,$A11) -> 0 | I11: =SUMIFS('Barrett, Ken'!M$4:M$31,'Barrett, Ken'!$E$4:$E$31,$A11)+SUMIFS('Brundage, Eric'!M$4:M$39,'Brundage, Eric'!$E$4:$E$39,$A11)+SUMIFS('Dubois, Joe'!M$4:M$70,'Dubois, Joe'!$E$4:$E$70,$A11)+SUMIFS('Gould, Kyle'!M$4:M$53,'Gould, Kyle'!$E$4:$E$53,$A11)+SUMIFS('Jamer, Douglas'!M$4:M$33,'Jamer, Douglas'!$E$4:$E$33,$A11)+SUMIFS('Kennedy, Michael'!M$4:M$87,'Kennedy, Michael'!$E$4:$E$87,$A11)+SUMIFS('Kennedy, Vince'!M$4:M$29,'Kennedy, Vince'!$E$4:$E$29,$A11)+SUMIFS('Morningstar, Jeremy J'!M$4:M$50,'Morningstar, Jeremy J'!$E$4:$E$50,$A11)+SUMIFS('Pendlebury, Jay'!M$4:M$31,'Pendlebury, Jay'!$E$4:$E$31,$A11)+SUMIFS('Poore, Jordan'!M$4:M$32,'Poore, Jordan'!$E$4:$E$32,$A11)+SUMIFS('Powers, Dave'!M$4:M$58,'Powers, Dave'!$E$4:$E$58,$A11) -> 0 | ... S11: =SUMIFS('Barrett, Ken'!W$4:W$31,'Barrett, Ken'!$E$4:$E$31,$A11)+SUMIFS('Brundage, Eric'!W$4:W$39,'Brundage, Eric'!$E$4:$E$39,$A11)+SUMIFS('Dubois, Joe'!W$4:W$70,'Dubois, Joe'!$E$4:$E$70,$A11)+SUMIFS('Gould, Kyle'!W$4:W$53,'Gould, Kyle'!$E$4:$E$53,$A11)+SUMIFS('Jamer, Douglas'!W$4:W$33,'Jamer, Douglas'!$E$4:$E$33,$A11)+SUMIFS('Kennedy, Michael'!W$4:W$87,'Kennedy, Michael'!$E$4:$E$87,$A11)+SUMIFS('Kennedy, Vince'!W$4:W$29,'Kennedy, Vince'!$E$4:$E$29,$A11)+SUMIFS('Morningstar, Jeremy J'!W$4:W$50,'Morningstar, Jeremy J'!$E$4:$E$50,$A11)+SUMIFS('Pendlebury, Jay'!W$4:W$31,'Pendlebury, Jay'!$E$4:$E$31,$A11)+SUMIFS('Poore, Jordan'!W$4:W$32,'Poore, Jordan'!$E$4:$E$32,$A11)+SUMIFS('Powers, Dave'!W$4:W$58,'Powers, Dave'!$E$4:$E$58,$A11) -> 0 | T11: =SUM(B11:S11) -> 0
